Workbook

Sheet README
A1: Goodyear (GT) - intrinsic value model
A3: Valuation date 2026-09-26; balance sheet 2026-06-30 (10-Q Q2-2026); price reference $5.125 (Nasdaq close 2026-09-25).
A4: Flow: Drivers (inputs) -> DCF_Bull / DCF_Base / DCF_Bear (live FCFF DCFs) -> EPV, Merton, Comps, SOTP, Transactions_Asset -> Summary (probability & method weights).
A5: Colour code: BLUE = hard-coded input, BLACK = formula, GREEN = link to another sheet, YELLOW fill = key assumption to change.
A6: To run your own case: edit yellow cells on Drivers (WACC used, scenario probabilities, revenue growth and SOI margin paths, capex %, restructuring, terminal growth, RONIC).
A7: Static (engine) outputs: MonteCarlo sheet, residual-income value and the margin sensitivity strip on Sensitivity come from scripts/valuation_engine.py (same DCF logic, seed 42); re-run the engine after changing drivers to refresh them.
A8: All $ in millions except per-share values. SOI = segment operating income (company non-GAAP measure, reconciled to GAAP in every 10-K segment note).
A9: Sources: SEC EDGAR (10-K 2015-2025, 10-Q Q1/Q2-2026, 8-K earnings releases 2015-2026, DEF 14A 2026), Goodyear investor presentations Q4-24..Q2-26, Yahoo Finance market data (2026-09-25).
A10: This workbook is analysis, not investment advice.

Sheet Summary
A1: Goodyear (GT) - probability-weighted intrinsic value
A3: Scenario DCF | B3: Probability | C3: EV ($m) | D3: Equity 6/30 ($m) | E3: Value/share ($) | F3: TV share of EV
A4: Bull | B4: =Drivers!B52 -> 0.15 | C4: =DCF_Bull!B40 -> 11724.047 | D4: =DCF_Bull!B43 -> 4814.047 | E4: =DCF_Bull!B45 -> 17.047803 | F4: =DCF_Bull!B41 -> 0.48264343
A5: Base | B5: =Drivers!C52 -> 0.45 | C5: =DCF_Base!B40 -> 7475.2713 | D5: =DCF_Base!B43 -> 565.27132 | E5: =DCF_Base!B45 -> 2.001774 | F5: =DCF_Base!B41 -> 0.45915929
A6: Bear | B6: =Drivers!D52 -> 0.28 | C6: =DCF_Bear!B40 -> 2932.9509 | D6: =DCF_Bear!B43 -> -3977.0491 | E6: =DCF_Bear!B45 -> 0 | F6: =DCF_Bear!B41 -> 0.45330218
A7: Distress (refinancing / restructuring) | B7: =Drivers!B62 -> 0.12 | E7: =Drivers!B63 -> 0.2
A8: Probability-weighted scenario DCF | B8: =SUM(B4:B7) -> 1 | E8: =SUMPRODUCT(B4:B7,E4:E7) -> 3.4819688
A10: Method | B10: Weight | C10: Low ($) | D10: Point ($) | E10: High ($) | H10: Why this weight
A11: Scenario-weighted FCFF DCF | B11: 0.35 | C11: =E6 -> 0 | D11: =E8 -> 3.4819688 | E11: =E4 -> 17.047803 | H11: Primary: explicit bull/base/bear/distress cash flows; captures leverage and the recovery path.
A12: Monte Carlo DCF (mean; P10 / P90) | B12: 0.2 | C12: =MonteCarlo!B6 -> 0 | D12: =MonteCarlo!B4 -> 3.194 | E12: =MonteCarlo!B10 -> 10.8603 | H12: Same engine, 20k draws over margins, growth, capex, WACC, g, RONIC with a leverage-based distress trigger.
A13: Merton option value on prob.-weighted EV | B13: 0.1 | C13: =Merton!B21 -> 0.54104933 | D13: =Merton!B14 -> 5.6089449 | E13: =Merton!D21 -> 21.717424 | H13: Thin equity stub on a large EV: values limited liability / upside optionality the floored DCF misses.
A14: Earnings power value (no growth, 6% SOI margin) | B14: 0.1 | C14: =EPV!B16 -> 0 | D14: =EPV!D16 -> 0.15447708 | E14: =EPV!F16 -> 5.1182171 | H14: Greenwald earnings power at mid-cycle 6% SOI margin, zero growth; isolates the growth bet.
A15: Comparable multiples (2027E) | B15: 0.15 | C15: =Comps!E46 -> 0 | D15: =Comps!E45 -> 5.95155 | E15: =Comps!E47 -> 13.160442 | H15: Peer EV/EBITDA & EV/EBIT and GT own-history multiple on 2027E; down-weighted: peers price off EUR/JPY rates and better FCF conversion.
A16: Sum of the parts (mid-cycle) | B16: 0.1 | C16: =SOTP!H14*0.5 -> 3.1659116 | D16: =SOTP!H14 -> 6.3318233 | E16: =SOTP!H14*1.5 -> 9.4977349 | H16: Segment multiples on mid-cycle margins; APAC is the most valuable unit per $ of sales.
A17: Residual income (cross-check, static) | B17: 0 | C17: 0 | D17: 3.5254 | E17: 8.5179 | H17: Shown as a cross-check only: book equity is distorted by AOCI pension losses and the 2025 DTA write-off.
A18: Precedent transactions (control reference) | B18: 0 | C18: =Transactions_Asset!B14 -> 0 | D18: =Transactions_Asset!B14 -> 0 | E18: =Transactions_Asset!B12 -> 4.4920441 | H18: Reference only: control multiples (Cooper 6.4x, OTR ~7x, Chemical ~4.3x) presume a buyer; antitrust limits obvious strategics.
A19: Asset-based (liquidation floor / tangible book) | B19: 0 | C19: 0 | D19: =Transactions_Asset!D27 -> 0 | E19: =Transactions_Asset!D29 -> 7.4444444 | H19: Floor/ceiling reference: liquidation leaves nothing for equity; tangible book is not economic value (ROIC < WACC).
A20: Dividend discount model | B20: 0 | H20: Excluded: no dividend since 2020 and none possible under current leverage.
A22: Blended intrinsic value per share ($) | B22: =SUM(B11:B20) -> 1 | D22: =SUMPRODUCT(B11:B20,D11:D20)/B22 -> 3.9597461
A23: Share price reference ($) | D23: =Drivers!B4 -> 5.125
A24: Upside / (downside) vs price | D24: =D22/D23-1 -> -0.22736662
A26: Monte Carlo distribution (DCF family)
B27: P10 | C27: P25 | D27: P50 | E27: P75 | F27: P90
A28: Value per share ($) | B28: =MonteCarlo!B6 -> 0 | C28: =MonteCarlo!B7 -> 0 | D28: =MonteCarlo!B8 -> 0 | E28: =MonteCarlo!B9 -> 4.9773 | F28: =MonteCarlo!B10 -> 10.8603
A29: P(intrinsic value > price) | B29: =MonteCarlo!B12 -> 0.2444
A31: Reverse DCF (static): implied long-run SOI margin at the market price | B31: 0.0669
A32: Reverse DCF (static): implied WACC at base-case cash flows | B32: 0.0828
A34: Analysis, not investment advice. See output/GT_degerleme_raporu.md for evidence, assumptions and falsifiers.

Sheet Drivers
A1: Drivers - every input used by the model (edit yellow cells)
A3: Market & share data
A4: Share price reference ($, 2026-09-25) | B4: 5.125 | L4: Yahoo Finance close; used only for reverse DCF / comparison
A5: Diluted shares (m) | B5: 290 | L5: 288m basic at 6/30/26 + ~2m equity awards (10-Q Q2-26)
A6: Roll-forward years (6/30/26 -> 9/26/26) | B6: 0.24
A8: Discount rate build
A9: Risk-free rate (10y UST) | B9: 0.052 | L9: 10y UST 5.18% on 2026-09-25 (Yahoo ^TNX)
A10: Equity risk premium | B10: 0.045 | L10: Implied US ERP range 4.2-4.6%
A11: Asset (unlevered) beta | B11: 1 | L11: Tire-peer asset betas 0.9-1.15; GT own 2y/3y/5y weekly beta 0.57/0.85/1.38 (corr <0.45)
A12: Debt beta | B12: 0.5 | L12: B+/BB- debt; implies expected debt return 7.45% vs 8.875% coupon on Jun-26 notes
A13: Target debt / value | B13: 0.5
A14: Effective tax-shield rate | B14: 0.1 | L14: Low: US & Luxembourg DTAs under full valuation allowance
A15: Unlevered cost of capital | B15: =B9+B11*B10 -> 0.097
A16: Expected cost of debt | B16: =B9+B12*B10 -> 0.0745
A17: Target debt / equity | B17: =B13/(1-B13) -> 1
A18: Equity beta at target leverage | B18: =B11+(B11-B12)*B17*(1-B14) -> 1.45
A19: Cost of equity at target leverage | B19: =B9+B18*B10 -> 0.11725
A20: WACC (computed) | B20: =(1-B13)*B19+B13*B16*(1-B14) -> 0.09215
A21: WACC used in all DCFs | B21: 0.0925 | L21: Rounded from computed WACC; sensitivity 8.25-10.25%
A22: Roll-forward factor (equity 6/30 -> 9/26) | B22: =(1+B19)^B6 -> 1.0269661
A24: Claims at 2026-06-30 ($m)
A25: Total debt | B25: 7190 | L25: 10-Q Q2-26: notes payable 359 + LTD due <1y 1,059 + LTD 5,772
A26: Cash & equivalents | B26: 861 | L26: 10-Q Q2-26 ($179m in countries with transfer restrictions)
A27: Net debt | B27: =B25-B26 -> 6329
A28: Pension & OPEB net deficit | B28: 369 | L28: 10-K 2025: US pension +77, non-US -215, OPEB -231
A29: Asbestos liability net of insurance receivable | B29: 50 | L29: 10-K 2025: gross 107 less receivable 57
A30: Minority interest (book) | B30: 162
A31: Total claims ahead of common equity | B31: =B27+B28+B29+B30 -> 6910
A33: Common forecast assumptions
A34: Revenue 2026E ($m) | B34: 17450 | L34: H1 actual 8,131 + H2E ~9,320; consensus 17,518
A35: Corporate cost 2026 ($m) | B35: 150 | L35: Q2-26 deck 'corporate other normal operating ~$150m'
A36: Corporate cost inflation | B36: 0.025
A37: Net working capital % of revenue | B37: 0.115 | L37: YE NWC/sales 10.3-13.0% in 2016-2025
A38: Factoring / securitization fees ($m/yr) | B38: 35 | L38: Cash cost of $830m off-B/S factoring + securitization; factored AR not added to debt
A39: Cash-tax floor 2026 ($m) | B39: 150 | L39: Foreign cash taxes ~$150-175m even in loss years (Q2-26 deck)
A40: Cash-tax floor growth | B40: 0.025
A41: Cash tax rate on (EBIT - restructuring - fees) to 2032 | B41: 0.2 | L41: US NOL / credit shield ($1.4bn US DTA under VA)
A42: Terminal cash tax rate | B42: 0.24
A43: D&A 2027 ($m) | B43: 900 | L43: 2026 guide ~$915m
A44: H2-2026 cash interest ($m) | B44: 225 | L44: FY26 interest ~$425m less H1 $200m
...

Sheet DCF_Bull
A1: FCFF DCF - BULL scenario ($m)
A3: Line item | B3: H2-2026 | C3: 2027 | D3: 2028 | E3: 2029 | F3: 2030 | G3: 2031 | H3: 2032 | I3: 2033 | J3: 2034 | K3: 2035
A4: Year (numeric) | B4: 2026.5 | C4: 2027 | D4: 2028 | E4: 2029 | F4: 2030 | G4: 2031 | H4: 2032 | I4: 2033 | J4: 2034 | K4: 2035
A5: Discount period t (years from 6/30/26, mid-year) | B5: 0.25 | C5: =C4-2026 -> 1 | D5: =D4-2026 -> 2 | E5: =E4-2026 -> 3 | F5: =F4-2026 -> 4 | G5: =G4-2026 -> 5 | H5: =H4-2026 -> 6 | I5: =I4-2026 -> 7 | J5: =J4-2026 -> 8 | K5: =K4-2026 -> 9
A6: Revenue | B6: =Drivers!$B$34 -> 17450 | C6: =B6*(1+C7) -> 17973.5 | D6: =C6*(1+D7) -> 18602.572 | E6: =D6*(1+E7) -> 19160.65 | F6: =E6*(1+F7) -> 19735.469 | G6: =F6*(1+G7) -> 20327.533 | H6: =G6*(1+H7) -> 20835.722 | I6: =H6*(1+I7) -> 21356.615 | J6: =I6*(1+J7) -> 21890.53 | K6: =J6*(1+K7) -> 22437.793
A7: Revenue growth | C7: =Drivers!C67 -> 0.03 | D7: =Drivers!D67 -> 0.035 | E7: =Drivers!E67 -> 0.03 | F7: =Drivers!F67 -> 0.03 | G7: =Drivers!G67 -> 0.03 | H7: =Drivers!H67 -> 0.025 | I7: =Drivers!I67 -> 0.025 | J7: =Drivers!J67 -> 0.025 | K7: =Drivers!K67 -> 0.025
A8: SOI margin | C8: =Drivers!C72 -> 0.06 | D8: =Drivers!D72 -> 0.07 | E8: =Drivers!E72 -> 0.078 | F8: =Drivers!F72 -> 0.08 | G8: =Drivers!G72 -> 0.08 | H8: =Drivers!H72 -> 0.08 | I8: =Drivers!I72 -> 0.08 | J8: =Drivers!J72 -> 0.08 | K8: =Drivers!K72 -> 0.08
A9: Segment operating income (SOI) | C9: =C6*C8 -> 1078.41 | D9: =D6*D8 -> 1302.1801 | E9: =E6*E8 -> 1494.5307 | F9: =F6*F8 -> 1578.8375 | G9: =G6*G8 -> 1626.2027 | H9: =H6*H8 -> 1666.8577 | I9: =I6*I8 -> 1708.5292 | J9: =J6*J8 -> 1751.2424 | K9: =K6*K8 -> 1795.0235
A10: Corporate cost | C10: =Drivers!$B$35*(1+Drivers!$B$36)^(C$4-2026) -> 153.75 | D10: =Drivers!$B$35*(1+Drivers!$B$36)^(D$4-2026) -> 157.59375 | E10: =Drivers!$B$35*(1+Drivers!$B$36)^(E$4-2026) -> 161.53359 | F10: =Drivers!$B$35*(1+Drivers!$B$36)^(F$4-2026) -> 165.57193 | G10: =Drivers!$B$35*(1+Drivers!$B$36)^(G$4-2026) -> 169.71123 | H10: =Drivers!$B$35*(1+Drivers!$B$36)^(H$4-2026) -> 173.95401 | I10: =Drivers!$B$35*(1+Drivers!$B$36)^(I$4-2026) -> 178.30286 | J10: =Drivers!$B$35*(1+Drivers!$B$36)^(J$4-2026) -> 182.76043 | K10: =Drivers!$B$35*(1+Drivers!$B$36)^(K$4-2026) -> 187.32945
A11: EBIT (SOI - corporate) | C11: =C9-C10 -> 924.66 | D11: =D9-D10 -> 1144.5863 | E11: =E9-E10 -> 1332.9971 | F11: =F9-F10 -> 1413.2656 | G11: =G9-G10 -> 1456.4914 | H11: =H9-H10 -> 1492.9037 | I11: =I9-I10 -> 1530.2263 | J11: =J9-J10 -> 1568.482 | K11: =K9-K10 -> 1607.694
A12: Capex | C12: =Drivers!B$55 -> 775 | D12: =Drivers!B$54*D6 -> 799.91062 | E12: =Drivers!B$54*E6 -> 823.90794 | F12: =Drivers!B$54*F6 -> 848.62517 | G12: =Drivers!B$54*G6 -> 874.08393 | H12: =Drivers!B$54*H6 -> 895.93603 | I12: =Drivers!B$54*I6 -> 918.33443 | J12: =Drivers!B$54*J6 -> 941.29279 | K12: =Drivers!B$54*K6 -> 964.82511
A13: D&A | C13: =Drivers!$B$43 -> 900 | D13: =0.5*C13+0.5*D12 -> 849.95531 | E13: =0.5*D13+0.5*E12 -> 836.93162 | F13: =0.5*E13+0.5*F12 -> 842.7784 | G13: =0.5*F13+0.5*G12 -> 858.43116 | H13: =0.5*G13+0.5*H12 -> 877.1836 | I13: =0.5*H13+0.5*I12 -> 897.75901 | J13: =0.5*I13+0.5*J12 -> 919.5259 | K13: =0.5*J13+0.5*K12 -> 942.1755
A14: Change in NWC | C14: =Drivers!$B$37*(C6-B6) -> 60.2025 | D14: =Drivers!$B$37*(D6-C6) -> 72.343337 | E14: =Drivers!$B$37*(E6-D6) -> 64.178875 | F14: =Drivers!$B$37*(F6-E6) -> 66.104241 | G14: =Drivers!$B$37*(G6-F6) -> 68.087369 | H14: =Drivers!$B$37*(H6-G6) -> 58.441658 | I14: =Drivers!$B$37*(I6-H6) -> 59.9027 | J14: =Drivers!$B$37*(J6-I6) -> 61.400267 | K14: =Drivers!$B$37*(K6-J6) -> 62.935274
A15: Restructuring cash | C15: =Drivers!B$56 -> 230 | D15: =Drivers!B$57 -> 110 | E15: =Drivers!B$58 -> 75 | F15: =Drivers!B$58 -> 75 | G15: =Drivers!B$58 -> 75 | H15: =Drivers!B$58 -> 75 | I15: =Drivers!B$58 -> 75 | J15: =Drivers!B$58 -> 75 | K15: =Drivers!B$58 -> 75
A16: Factoring / securitization fees | C16: =Drivers!$B$38 -> 35 | D16: =Drivers!$B$38 -> 35 | E16: =Drivers!$B$38 -> 35 | F16: =Drivers!$B$38 -> 35 | G16: =Drivers!$B$38 -> 35 | H16: =Drivers!$B$38 -> 35 | I16: =Drivers!$B$38 -> 35 | J16: =Drivers!$B$38 -> 35 | K16: =Drivers!$B$38 -> 35
A17: Deferred revenue reversal (non-cash SOI) | C17: =Drivers!C$48 -> 55 | D17: =Drivers!D$48 -> 55 | E17: =Drivers!E$48 -> 55 | F17: =Drivers!F$48 -> 55 | G17: =Drivers!G$48 -> 40 | H17: =Drivers!H$48 -> 0 | I17: =Drivers!I$48 -> 0 | J17: =Drivers!J$48 -> 0 | K17: =Drivers!K$48 -> 0
A18: Taxable base (EBIT - restructuring - fees) | C18: =C11-C15-C16 -> 659.66 | D18: =D11-D15-D16 -> 999.58632 | E18: =E11-E15-E16 -> 1222.9971 | F18: =F11-F15-F16 -> 1303.2656 | G18: =G11-G15-G16 -> 1346.4914 | H18: =H11-H15-H16 -> 1382.9037 | I18: =I11-I15-I16 -> 1420.2263 | J18: =J11-J15-J16 -> 1458.482 | K18: =K11-K15-K16 -> 1497.694
A19: Cash-tax floor | C19: =Drivers!$B$39*(1+Drivers!$B$40)^(C$4-2026) -> 153.75 | D19: =Drivers!$B$39*(1+Drivers!$B$40)^(D$4-2026) -> 157.59375 | E19: =Drivers!$B$39*(1+Drivers!$B$40)^(E$4-2026) -> 161.53359 | F19: =Drivers!$B$39*(1+Drivers!$B$40)^(F$4-2026) -> 165.57193 | G19: =Drivers!$B$39*(1+Drivers!$B$40)^(G$4-2026) -> 169.71123 | H19: =Drivers!$B$39*(1+Drivers!$B$40)^(H$4-2026) -> 173.95401 | I19: =Drivers!$B$39*(1+Drivers!$B$40)^(I$4-2026) -> 178.30286 | J19: =Drivers!$B$39*(1+Drivers!$B$40)^(J$4-2026) -> 182.76043 | K19: =Drivers!$B$39*(1+Drivers!$B$40)^(K$4-2026) -> 187.32945
A20: Cash tax rate | C20: =IF(C$4<=2032,Drivers!$B$41,Drivers!$B$42) -> 0.2 | D20: =IF(D$4<=2032,Drivers!$B$41,Drivers!$B$42) -> 0.2 | E20: =IF(E$4<=2032,Drivers!$B$41,Drivers!$B$42) -> 0.2 | F20: =IF(F$4<=2032,Drivers!$B$41,Drivers!$B$42) -> 0.2 | G20: =IF(G$4<=2032,Drivers!$B$41,Drivers!$B$42) -> 0.2 | H20: =IF(H$4<=2032,Drivers!$B$41,Drivers!$B$42) -> 0.2 | I20: =IF(I$4<=2032,Drivers!$B$41,Drivers!$B$42) -> 0.24 | J20: =IF(J$4<=2032,Drivers!$B$41,Drivers!$B$42) -> 0.24 | K20: =IF(K$4<=2032,Drivers!$B$41,Drivers!$B$42) -> 0.24
A21: Cash taxes | C21: =MAX(C19,C20*C18) -> 153.75 | D21: =MAX(D19,D20*D18) -> 199.91726 | E21: =MAX(E19,E20*E18) -> 244.59942 | F21: =MAX(F19,F20*F18) -> 260.65312 | G21: =MAX(G19,G20*G18) -> 269.29829 | H21: =MAX(H19,H20*H18) -> 276.58074 | I21: =MAX(I19,I20*I18) -> 340.85431 | J21: =MAX(J19,J20*J18) -> 350.03567 | K21: =MAX(K19,K20*K18) -> 359.44656
A22: Free cash flow to firm (FCFF) | B22: =Drivers!B$53 -> 962 | C22: =C11-C21+C13-C12-C14-C15-C16-C17 -> 515.7075 | D22: =D11-D21+D13-D12-D14-D15-D16-D17 -> 722.37041 | E22: =E11-E21+E13-E12-E14-E15-E16-E17 -> 872.24248 | F22: =F11-F21+F13-F12-F14-F15-F16-F17 -> 915.66146 | G22: =G11-G21+G13-G12-G14-G15-G16-G17 -> 953.45301 | H22: =H11-H21+H13-H12-H14-H15-H16-H17 -> 1029.1289 | I22: =I11-I21+I13-I12-I14-I15-I16-I17 -> 998.89388 | J22: =J11-J21+J13-J12-J14-J15-J16-J17 -> 1025.2791 | K22: =K11-K21+K13-K12-K14-K15-K16-K17 -> 1052.6626
A23: Discount factor | B23: =1/(1+Drivers!$B$21)^B5 -> 0.97812563 | C23: =1/(1+Drivers!$B$21)^C5 -> 0.91533181 | D23: =1/(1+Drivers!$B$21)^D5 -> 0.83783232 | E23: =1/(1+Drivers!$B$21)^E5 -> 0.76689457 | F23: =1/(1+Drivers!$B$21)^F5 -> 0.70196299 | G23: =1/(1+Drivers!$B$21)^G5 -> 0.64252906 | H23: =1/(1+Drivers!$B$21)^H5 -> 0.58812728 | I23: =1/(1+Drivers!$B$21)^I5 -> 0.53833161 | ... K23: =1/(1+Drivers!$B$21)^K5 -> 0.45103162
A24: PV of FCFF | B24: =B22*B23 -> 940.95686 | C24: =C22*C23 -> 472.04348 | D24: =D22*D23 -> 605.22528 | E24: =E22*E23 -> 668.91802 | F24: =F22*F23 -> 642.76046 | G24: =G22*G23 -> 612.62126 | H24: =H22*H23 -> 605.25877 | I24: =I22*I23 -> 537.73615 | ... K24: =K22*K23 -> 474.7841
A25: EBITDA (SOI + D&A - corporate) | C25: =C11+C13 -> 1824.66 | D25: =D11+D13 -> 1994.5416 | E25: =E11+E13 -> 2169.9287 | F25: =F11+F13 -> 2256.044 | G25: =G11+G13 -> 2314.9226 | H25: =H11+H13 -> 2370.0873 | I25: =I11+I13 -> 2427.9853 | J25: =J11+J13 -> 2488.0079 | K25: =K11+K13 -> 2549.8695
A28: Terminal value (Gordon, value-driver form)
A29: Terminal growth g | B29: =Drivers!B$59 -> 0.02
A30: RONIC | B30: =Drivers!B$60 -> 0.11
A31: Revenue 2036 | B31: =K6*(1+B29) -> 22886.549
A32: Corporate cost 2036 | B32: =Drivers!$B$35*(1+Drivers!$B$36)^(2036-2026) -> 192.01268
A33: EBIT 2036 (2035 SOI margin) | B33: =B31*K8-B32 -> 1638.9112
A34: NOPAT 2036 after normalized restructuring & fees | B34: =(B33-Drivers!B$58-Drivers!$B$38)*(1-Drivers!$B$42) -> 1161.9725
A35: Terminal value at end-2035 | B35: =B34*(1-B29/B30)/(Drivers!$B$21-B29) -> 13113.17
A36: PV of terminal value (t = 9.5) | B36: =B35/(1+Drivers!$B$21)^9.5 -> 5658.5343
A38: Valuation
A39: Sum of PV of FCFF (H2-26 to 2035) | B39: =SUM(B24:K24) -> 6065.5128
A40: Enterprise value at 6/30/26 | B40: =B39+B36 -> 11724.047
A41: Terminal value share of EV | B41: =B36/B40 -> 0.48264343
A42: Less: claims (net debt, pension, asbestos, minority) | B42: =Drivers!$B$31 -> 6910
A43: Equity value at 6/30/26 | B43: =B40-B42 -> 4814.047
A44: Equity value at 9/26/26 (floored at zero) | B44: =MAX(B43,0)*Drivers!$B$22 -> 4943.8629
...

Sheet DCF_Base
A1: FCFF DCF - BASE scenario ($m)
A3: Line item | B3: H2-2026 | C3: 2027 | D3: 2028 | E3: 2029 | F3: 2030 | G3: 2031 | H3: 2032 | I3: 2033 | J3: 2034 | K3: 2035
A4: Year (numeric) | B4: 2026.5 | C4: 2027 | D4: 2028 | E4: 2029 | F4: 2030 | G4: 2031 | H4: 2032 | I4: 2033 | J4: 2034 | K4: 2035
A5: Discount period t (years from 6/30/26, mid-year) | B5: 0.25 | C5: =C4-2026 -> 1 | D5: =D4-2026 -> 2 | E5: =E4-2026 -> 3 | F5: =F4-2026 -> 4 | G5: =G4-2026 -> 5 | H5: =H4-2026 -> 6 | I5: =I4-2026 -> 7 | J5: =J4-2026 -> 8 | K5: =K4-2026 -> 9
A6: Revenue | B6: =Drivers!$B$34 -> 17450 | C6: =B6*(1+C7) -> 17799 | D6: =C6*(1+D7) -> 18243.975 | E6: =D6*(1+E7) -> 18700.074 | F6: =E6*(1+F7) -> 19167.576 | G6: =F6*(1+G7) -> 19646.766 | H6: =G6*(1+H7) -> 20039.701 | I6: =H6*(1+I7) -> 20440.495 | J6: =I6*(1+J7) -> 20849.305 | K6: =J6*(1+K7) -> 21266.291
A7: Revenue growth | C7: =Drivers!C68 -> 0.02 | D7: =Drivers!D68 -> 0.025 | E7: =Drivers!E68 -> 0.025 | F7: =Drivers!F68 -> 0.025 | G7: =Drivers!G68 -> 0.025 | H7: =Drivers!H68 -> 0.02 | I7: =Drivers!I68 -> 0.02 | J7: =Drivers!J68 -> 0.02 | K7: =Drivers!K68 -> 0.02
A8: SOI margin | C8: =Drivers!C73 -> 0.05 | D8: =Drivers!D73 -> 0.056 | E8: =Drivers!E73 -> 0.059 | F8: =Drivers!F73 -> 0.06 | G8: =Drivers!G73 -> 0.06 | H8: =Drivers!H73 -> 0.06 | I8: =Drivers!I73 -> 0.06 | J8: =Drivers!J73 -> 0.06 | K8: =Drivers!K73 -> 0.06
A9: Segment operating income (SOI) | C9: =C6*C8 -> 889.95 | D9: =D6*D8 -> 1021.6626 | E9: =E6*E8 -> 1103.3044 | F9: =F6*F8 -> 1150.0546 | G9: =G6*G8 -> 1178.8059 | H9: =H6*H8 -> 1202.3821 | I9: =I6*I8 -> 1226.4297 | J9: =J6*J8 -> 1250.9583 | K9: =K6*K8 -> 1275.9775
A10: Corporate cost | C10: =Drivers!$B$35*(1+Drivers!$B$36)^(C$4-2026) -> 153.75 | D10: =Drivers!$B$35*(1+Drivers!$B$36)^(D$4-2026) -> 157.59375 | E10: =Drivers!$B$35*(1+Drivers!$B$36)^(E$4-2026) -> 161.53359 | F10: =Drivers!$B$35*(1+Drivers!$B$36)^(F$4-2026) -> 165.57193 | G10: =Drivers!$B$35*(1+Drivers!$B$36)^(G$4-2026) -> 169.71123 | H10: =Drivers!$B$35*(1+Drivers!$B$36)^(H$4-2026) -> 173.95401 | I10: =Drivers!$B$35*(1+Drivers!$B$36)^(I$4-2026) -> 178.30286 | J10: =Drivers!$B$35*(1+Drivers!$B$36)^(J$4-2026) -> 182.76043 | K10: =Drivers!$B$35*(1+Drivers!$B$36)^(K$4-2026) -> 187.32945
A11: EBIT (SOI - corporate) | C11: =C9-C10 -> 736.2 | D11: =D9-D10 -> 864.06885 | E11: =E9-E10 -> 941.77079 | F11: =F9-F10 -> 984.48264 | G11: =G9-G10 -> 1009.0947 | H11: =H9-H10 -> 1028.428 | I11: =I9-I10 -> 1048.1268 | J11: =J9-J10 -> 1068.1979 | K11: =K9-K10 -> 1088.648
A12: Capex | C12: =Drivers!C$55 -> 775 | D12: =Drivers!C$54*D6 -> 839.22285 | E12: =Drivers!C$54*E6 -> 860.20342 | F12: =Drivers!C$54*F6 -> 881.70851 | G12: =Drivers!C$54*G6 -> 903.75122 | H12: =Drivers!C$54*H6 -> 921.82624 | I12: =Drivers!C$54*I6 -> 940.26277 | J12: =Drivers!C$54*J6 -> 959.06802 | K12: =Drivers!C$54*K6 -> 978.24938
A13: D&A | C13: =Drivers!$B$43 -> 900 | D13: =0.5*C13+0.5*D12 -> 869.61143 | E13: =0.5*D13+0.5*E12 -> 864.90742 | F13: =0.5*E13+0.5*F12 -> 873.30796 | G13: =0.5*F13+0.5*G12 -> 888.52959 | H13: =0.5*G13+0.5*H12 -> 905.17792 | I13: =0.5*H13+0.5*I12 -> 922.72034 | J13: =0.5*I13+0.5*J12 -> 940.89418 | K13: =0.5*J13+0.5*K12 -> 959.57178
A14: Change in NWC | C14: =Drivers!$B$37*(C6-B6) -> 40.135 | D14: =Drivers!$B$37*(D6-C6) -> 51.172125 | E14: =Drivers!$B$37*(E6-D6) -> 52.451428 | F14: =Drivers!$B$37*(F6-E6) -> 53.762714 | G14: =Drivers!$B$37*(G6-F6) -> 55.106782 | H14: =Drivers!$B$37*(H6-G6) -> 45.187561 | I14: =Drivers!$B$37*(I6-H6) -> 46.091312 | J14: =Drivers!$B$37*(J6-I6) -> 47.013138 | K14: =Drivers!$B$37*(K6-J6) -> 47.953401
A15: Restructuring cash | C15: =Drivers!C$56 -> 250 | D15: =Drivers!C$57 -> 150 | E15: =Drivers!C$58 -> 100 | F15: =Drivers!C$58 -> 100 | G15: =Drivers!C$58 -> 100 | H15: =Drivers!C$58 -> 100 | I15: =Drivers!C$58 -> 100 | J15: =Drivers!C$58 -> 100 | K15: =Drivers!C$58 -> 100
A16: Factoring / securitization fees | C16: =Drivers!$B$38 -> 35 | D16: =Drivers!$B$38 -> 35 | E16: =Drivers!$B$38 -> 35 | F16: =Drivers!$B$38 -> 35 | G16: =Drivers!$B$38 -> 35 | H16: =Drivers!$B$38 -> 35 | I16: =Drivers!$B$38 -> 35 | J16: =Drivers!$B$38 -> 35 | K16: =Drivers!$B$38 -> 35
A17: Deferred revenue reversal (non-cash SOI) | C17: =Drivers!C$48 -> 55 | D17: =Drivers!D$48 -> 55 | E17: =Drivers!E$48 -> 55 | F17: =Drivers!F$48 -> 55 | G17: =Drivers!G$48 -> 40 | H17: =Drivers!H$48 -> 0 | I17: =Drivers!I$48 -> 0 | J17: =Drivers!J$48 -> 0 | K17: =Drivers!K$48 -> 0
A18: Taxable base (EBIT - restructuring - fees) | C18: =C11-C15-C16 -> 451.2 | D18: =D11-D15-D16 -> 679.06885 | E18: =E11-E15-E16 -> 806.77079 | F18: =F11-F15-F16 -> 849.48264 | G18: =G11-G15-G16 -> 874.09471 | H18: =H11-H15-H16 -> 893.42804 | I18: =I11-I15-I16 -> 913.12684 | J18: =J11-J15-J16 -> 933.19786 | K18: =K11-K15-K16 -> 953.64801
A19: Cash-tax floor | C19: =Drivers!$B$39*(1+Drivers!$B$40)^(C$4-2026) -> 153.75 | D19: =Drivers!$B$39*(1+Drivers!$B$40)^(D$4-2026) -> 157.59375 | E19: =Drivers!$B$39*(1+Drivers!$B$40)^(E$4-2026) -> 161.53359 | F19: =Drivers!$B$39*(1+Drivers!$B$40)^(F$4-2026) -> 165.57193 | G19: =Drivers!$B$39*(1+Drivers!$B$40)^(G$4-2026) -> 169.71123 | H19: =Drivers!$B$39*(1+Drivers!$B$40)^(H$4-2026) -> 173.95401 | I19: =Drivers!$B$39*(1+Drivers!$B$40)^(I$4-2026) -> 178.30286 | J19: =Drivers!$B$39*(1+Drivers!$B$40)^(J$4-2026) -> 182.76043 | K19: =Drivers!$B$39*(1+Drivers!$B$40)^(K$4-2026) -> 187.32945
A20: Cash tax rate | C20: =IF(C$4<=2032,Drivers!$B$41,Drivers!$B$42) -> 0.2 | D20: =IF(D$4<=2032,Drivers!$B$41,Drivers!$B$42) -> 0.2 | E20: =IF(E$4<=2032,Drivers!$B$41,Drivers!$B$42) -> 0.2 | F20: =IF(F$4<=2032,Drivers!$B$41,Drivers!$B$42) -> 0.2 | G20: =IF(G$4<=2032,Drivers!$B$41,Drivers!$B$42) -> 0.2 | H20: =IF(H$4<=2032,Drivers!$B$41,Drivers!$B$42) -> 0.2 | I20: =IF(I$4<=2032,Drivers!$B$41,Drivers!$B$42) -> 0.24 | J20: =IF(J$4<=2032,Drivers!$B$41,Drivers!$B$42) -> 0.24 | K20: =IF(K$4<=2032,Drivers!$B$41,Drivers!$B$42) -> 0.24
A21: Cash taxes | C21: =MAX(C19,C20*C18) -> 153.75 | D21: =MAX(D19,D20*D18) -> 157.59375 | E21: =MAX(E19,E20*E18) -> 161.53359 | F21: =MAX(F19,F20*F18) -> 169.89653 | G21: =MAX(G19,G20*G18) -> 174.81894 | H21: =MAX(H19,H20*H18) -> 178.68561 | I21: =MAX(I19,I20*I18) -> 219.15044 | J21: =MAX(J19,J20*J18) -> 223.96749 | K21: =MAX(K19,K20*K18) -> 228.87552
A22: Free cash flow to firm (FCFF) | B22: =Drivers!C$53 -> 862 | C22: =C11-C21+C13-C12-C14-C15-C16-C17 -> 327.315 | D22: =D11-D21+D13-D12-D14-D15-D16-D17 -> 445.69155 | E22: =E11-E21+E13-E12-E14-E15-E16-E17 -> 542.48977 | F22: =F11-F21+F13-F12-F14-F15-F16-F17 -> 562.42286 | G22: =G11-G21+G13-G12-G14-G15-G16-G17 -> 588.94736 | H22: =H11-H21+H13-H12-H14-H15-H16-H17 -> 652.90655 | I22: =I11-I21+I13-I12-I14-I15-I16-I17 -> 630.34266 | J22: =J11-J21+J13-J12-J14-J15-J16-J17 -> 644.04339 | K22: =K11-K21+K13-K12-K14-K15-K16-K17 -> 658.14149
A23: Discount factor | B23: =1/(1+Drivers!$B$21)^B5 -> 0.97812563 | C23: =1/(1+Drivers!$B$21)^C5 -> 0.91533181 | D23: =1/(1+Drivers!$B$21)^D5 -> 0.83783232 | E23: =1/(1+Drivers!$B$21)^E5 -> 0.76689457 | F23: =1/(1+Drivers!$B$21)^F5 -> 0.70196299 | G23: =1/(1+Drivers!$B$21)^G5 -> 0.64252906 | H23: =1/(1+Drivers!$B$21)^H5 -> 0.58812728 | I23: =1/(1+Drivers!$B$21)^I5 -> 0.53833161 | ... K23: =1/(1+Drivers!$B$21)^K5 -> 0.45103162
A24: PV of FCFF | B24: =B22*B23 -> 843.14429 | C24: =C22*C23 -> 299.60183 | D24: =D22*D23 -> 373.41478 | E24: =E22*E23 -> 416.03246 | F24: =F22*F23 -> 394.80003 | G24: =G22*G23 -> 378.41579 | H24: =H22*H23 -> 383.99215 | I24: =I22*I23 -> 339.33338 | ... K24: =K22*K23 -> 296.84262
A25: EBITDA (SOI + D&A - corporate) | C25: =C11+C13 -> 1636.2 | D25: =D11+D13 -> 1733.6803 | E25: =E11+E13 -> 1806.6782 | F25: =F11+F13 -> 1857.7906 | G25: =G11+G13 -> 1897.6243 | H25: =H11+H13 -> 1933.606 | I25: =I11+I13 -> 1970.8472 | J25: =J11+J13 -> 2009.092 | K25: =K11+K13 -> 2048.2198
A28: Terminal value (Gordon, value-driver form)
A29: Terminal growth g | B29: =Drivers!C$59 -> 0.015
A30: RONIC | B30: =Drivers!C$60 -> 0.0925
A31: Revenue 2036 | B31: =K6*(1+B29) -> 21585.285
A32: Corporate cost 2036 | B32: =Drivers!$B$35*(1+Drivers!$B$36)^(2036-2026) -> 192.01268
A33: EBIT 2036 (2035 SOI margin) | B33: =B31*K8-B32 -> 1103.1044
A34: NOPAT 2036 after normalized restructuring & fees | B34: =(B33-Drivers!C$58-Drivers!$B$38)*(1-Drivers!$B$42) -> 735.75937
A35: Terminal value at end-2035 | B35: =B34*(1-B29/B30)/(Drivers!$B$21-B29) -> 7954.1554
A36: PV of terminal value (t = 9.5) | B36: =B35/(1+Drivers!$B$21)^9.5 -> 3432.3403
A38: Valuation
A39: Sum of PV of FCFF (H2-26 to 2035) | B39: =SUM(B24:K24) -> 4042.931
A40: Enterprise value at 6/30/26 | B40: =B39+B36 -> 7475.2713
A41: Terminal value share of EV | B41: =B36/B40 -> 0.45915929
A42: Less: claims (net debt, pension, asbestos, minority) | B42: =Drivers!$B$31 -> 6910
A43: Equity value at 6/30/26 | B43: =B40-B42 -> 565.27132
A44: Equity value at 9/26/26 (floored at zero) | B44: =MAX(B43,0)*Drivers!$B$22 -> 580.51446
...

Sheet DCF_Bear
A1: FCFF DCF - BEAR scenario ($m)
A3: Line item | B3: H2-2026 | C3: 2027 | D3: 2028 | E3: 2029 | F3: 2030 | G3: 2031 | H3: 2032 | I3: 2033 | J3: 2034 | K3: 2035
A4: Year (numeric) | B4: 2026.5 | C4: 2027 | D4: 2028 | E4: 2029 | F4: 2030 | G4: 2031 | H4: 2032 | I4: 2033 | J4: 2034 | K4: 2035
A5: Discount period t (years from 6/30/26, mid-year) | B5: 0.25 | C5: =C4-2026 -> 1 | D5: =D4-2026 -> 2 | E5: =E4-2026 -> 3 | F5: =F4-2026 -> 4 | G5: =G4-2026 -> 5 | H5: =H4-2026 -> 6 | I5: =I4-2026 -> 7 | J5: =J4-2026 -> 8 | K5: =K4-2026 -> 9
A6: Revenue | B6: =Drivers!$B$34 -> 17450 | C6: =B6*(1+C7) -> 17537.25 | D6: =C6*(1+D7) -> 17712.623 | E6: =D6*(1+E7) -> 17889.749 | F6: =E6*(1+F7) -> 18068.646 | G6: =F6*(1+G7) -> 18249.333 | H6: =G6*(1+H7) -> 18431.826 | I6: =H6*(1+I7) -> 18616.144 | J6: =I6*(1+J7) -> 18802.306 | K6: =J6*(1+K7) -> 18990.329
A7: Revenue growth | C7: =Drivers!C69 -> 0.005 | D7: =Drivers!D69 -> 0.01 | E7: =Drivers!E69 -> 0.01 | F7: =Drivers!F69 -> 0.01 | G7: =Drivers!G69 -> 0.01 | H7: =Drivers!H69 -> 0.01 | I7: =Drivers!I69 -> 0.01 | J7: =Drivers!J69 -> 0.01 | K7: =Drivers!K69 -> 0.01
A8: SOI margin | C8: =Drivers!C74 -> 0.038 | D8: =Drivers!D74 -> 0.04 | E8: =Drivers!E74 -> 0.04 | F8: =Drivers!F74 -> 0.04 | G8: =Drivers!G74 -> 0.04 | H8: =Drivers!H74 -> 0.04 | I8: =Drivers!I74 -> 0.04 | J8: =Drivers!J74 -> 0.04 | K8: =Drivers!K74 -> 0.04
A9: Segment operating income (SOI) | C9: =C6*C8 -> 666.4155 | D9: =D6*D8 -> 708.5049 | E9: =E6*E8 -> 715.58995 | F9: =F6*F8 -> 722.74585 | G9: =G6*G8 -> 729.97331 | H9: =H6*H8 -> 737.27304 | I9: =I6*I8 -> 744.64577 | J9: =J6*J8 -> 752.09223 | K9: =K6*K8 -> 759.61315
A10: Corporate cost | C10: =Drivers!$B$35*(1+Drivers!$B$36)^(C$4-2026) -> 153.75 | D10: =Drivers!$B$35*(1+Drivers!$B$36)^(D$4-2026) -> 157.59375 | E10: =Drivers!$B$35*(1+Drivers!$B$36)^(E$4-2026) -> 161.53359 | F10: =Drivers!$B$35*(1+Drivers!$B$36)^(F$4-2026) -> 165.57193 | G10: =Drivers!$B$35*(1+Drivers!$B$36)^(G$4-2026) -> 169.71123 | H10: =Drivers!$B$35*(1+Drivers!$B$36)^(H$4-2026) -> 173.95401 | I10: =Drivers!$B$35*(1+Drivers!$B$36)^(I$4-2026) -> 178.30286 | J10: =Drivers!$B$35*(1+Drivers!$B$36)^(J$4-2026) -> 182.76043 | K10: =Drivers!$B$35*(1+Drivers!$B$36)^(K$4-2026) -> 187.32945
A11: EBIT (SOI - corporate) | C11: =C9-C10 -> 512.6655 | D11: =D9-D10 -> 550.91115 | E11: =E9-E10 -> 554.05636 | F11: =F9-F10 -> 557.17391 | G11: =G9-G10 -> 560.26208 | H11: =H9-H10 -> 563.31903 | I11: =I9-I10 -> 566.34291 | J11: =J9-J10 -> 569.33179 | K11: =K9-K10 -> 572.2837
A12: Capex | C12: =Drivers!D$55 -> 750 | D12: =Drivers!D$54*D6 -> 850.20588 | E12: =Drivers!D$54*E6 -> 858.70794 | F12: =Drivers!D$54*F6 -> 867.29502 | G12: =Drivers!D$54*G6 -> 875.96797 | H12: =Drivers!D$54*H6 -> 884.72765 | I12: =Drivers!D$54*I6 -> 893.57492 | J12: =Drivers!D$54*J6 -> 902.51067 | K12: =Drivers!D$54*K6 -> 911.53578
A13: D&A | C13: =Drivers!$B$43 -> 900 | D13: =0.5*C13+0.5*D12 -> 875.10294 | E13: =0.5*D13+0.5*E12 -> 866.90544 | F13: =0.5*E13+0.5*F12 -> 867.10023 | G13: =0.5*F13+0.5*G12 -> 871.5341 | H13: =0.5*G13+0.5*H12 -> 878.13087 | I13: =0.5*H13+0.5*I12 -> 885.8529 | J13: =0.5*I13+0.5*J12 -> 894.18179 | K13: =0.5*J13+0.5*K12 -> 902.85878
A14: Change in NWC | C14: =Drivers!$B$37*(C6-B6) -> 10.03375 | D14: =Drivers!$B$37*(D6-C6) -> 20.167838 | E14: =Drivers!$B$37*(E6-D6) -> 20.369516 | F14: =Drivers!$B$37*(F6-E6) -> 20.573211 | G14: =Drivers!$B$37*(G6-F6) -> 20.778943 | H14: =Drivers!$B$37*(H6-G6) -> 20.986733 | I14: =Drivers!$B$37*(I6-H6) -> 21.1966 | J14: =Drivers!$B$37*(J6-I6) -> 21.408566 | K14: =Drivers!$B$37*(K6-J6) -> 21.622652
A15: Restructuring cash | C15: =Drivers!D$56 -> 275 | D15: =Drivers!D$57 -> 175 | E15: =Drivers!D$58 -> 150 | F15: =Drivers!D$58 -> 150 | G15: =Drivers!D$58 -> 150 | H15: =Drivers!D$58 -> 150 | I15: =Drivers!D$58 -> 150 | J15: =Drivers!D$58 -> 150 | K15: =Drivers!D$58 -> 150
A16: Factoring / securitization fees | C16: =Drivers!$B$38 -> 35 | D16: =Drivers!$B$38 -> 35 | E16: =Drivers!$B$38 -> 35 | F16: =Drivers!$B$38 -> 35 | G16: =Drivers!$B$38 -> 35 | H16: =Drivers!$B$38 -> 35 | I16: =Drivers!$B$38 -> 35 | J16: =Drivers!$B$38 -> 35 | K16: =Drivers!$B$38 -> 35
A17: Deferred revenue reversal (non-cash SOI) | C17: =Drivers!C$48 -> 55 | D17: =Drivers!D$48 -> 55 | E17: =Drivers!E$48 -> 55 | F17: =Drivers!F$48 -> 55 | G17: =Drivers!G$48 -> 40 | H17: =Drivers!H$48 -> 0 | I17: =Drivers!I$48 -> 0 | J17: =Drivers!J$48 -> 0 | K17: =Drivers!K$48 -> 0
A18: Taxable base (EBIT - restructuring - fees) | C18: =C11-C15-C16 -> 202.6655 | D18: =D11-D15-D16 -> 340.91115 | E18: =E11-E15-E16 -> 369.05636 | F18: =F11-F15-F16 -> 372.17391 | G18: =G11-G15-G16 -> 375.26208 | H18: =H11-H15-H16 -> 378.31903 | I18: =I11-I15-I16 -> 381.34291 | J18: =J11-J15-J16 -> 384.33179 | K18: =K11-K15-K16 -> 387.2837
A19: Cash-tax floor | C19: =Drivers!$B$39*(1+Drivers!$B$40)^(C$4-2026) -> 153.75 | D19: =Drivers!$B$39*(1+Drivers!$B$40)^(D$4-2026) -> 157.59375 | E19: =Drivers!$B$39*(1+Drivers!$B$40)^(E$4-2026) -> 161.53359 | F19: =Drivers!$B$39*(1+Drivers!$B$40)^(F$4-2026) -> 165.57193 | G19: =Drivers!$B$39*(1+Drivers!$B$40)^(G$4-2026) -> 169.71123 | H19: =Drivers!$B$39*(1+Drivers!$B$40)^(H$4-2026) -> 173.95401 | I19: =Drivers!$B$39*(1+Drivers!$B$40)^(I$4-2026) -> 178.30286 | J19: =Drivers!$B$39*(1+Drivers!$B$40)^(J$4-2026) -> 182.76043 | K19: =Drivers!$B$39*(1+Drivers!$B$40)^(K$4-2026) -> 187.32945
A20: Cash tax rate | C20: =IF(C$4<=2032,Drivers!$B$41,Drivers!$B$42) -> 0.2 | D20: =IF(D$4<=2032,Drivers!$B$41,Drivers!$B$42) -> 0.2 | E20: =IF(E$4<=2032,Drivers!$B$41,Drivers!$B$42) -> 0.2 | F20: =IF(F$4<=2032,Drivers!$B$41,Drivers!$B$42) -> 0.2 | G20: =IF(G$4<=2032,Drivers!$B$41,Drivers!$B$42) -> 0.2 | H20: =IF(H$4<=2032,Drivers!$B$41,Drivers!$B$42) -> 0.2 | I20: =IF(I$4<=2032,Drivers!$B$41,Drivers!$B$42) -> 0.24 | J20: =IF(J$4<=2032,Drivers!$B$41,Drivers!$B$42) -> 0.24 | K20: =IF(K$4<=2032,Drivers!$B$41,Drivers!$B$42) -> 0.24
A21: Cash taxes | C21: =MAX(C19,C20*C18) -> 153.75 | D21: =MAX(D19,D20*D18) -> 157.59375 | E21: =MAX(E19,E20*E18) -> 161.53359 | F21: =MAX(F19,F20*F18) -> 165.57193 | G21: =MAX(G19,G20*G18) -> 169.71123 | H21: =MAX(H19,H20*H18) -> 173.95401 | I21: =MAX(I19,I20*I18) -> 178.30286 | J21: =MAX(J19,J20*J18) -> 182.76043 | K21: =MAX(K19,K20*K18) -> 187.32945
A22: Free cash flow to firm (FCFF) | B22: =Drivers!D$53 -> 737 | C22: =C11-C21+C13-C12-C14-C15-C16-C17 -> 133.88175 | D22: =D11-D21+D13-D12-D14-D15-D16-D17 -> 133.04662 | E22: =E11-E21+E13-E12-E14-E15-E16-E17 -> 140.35075 | F22: =F11-F21+F13-F12-F14-F15-F16-F17 -> 130.83398 | G22: =G11-G21+G13-G12-G14-G15-G16-G17 -> 140.33803 | H22: =H11-H21+H13-H12-H14-H15-H16-H17 -> 176.78151 | I22: =I11-I21+I13-I12-I14-I15-I16-I17 -> 174.12142 | J22: =J11-J21+J13-J12-J14-J15-J16-J17 -> 171.83391 | K22: =K11-K21+K13-K12-K14-K15-K16-K17 -> 169.65461
A23: Discount factor | B23: =1/(1+Drivers!$B$21)^B5 -> 0.97812563 | C23: =1/(1+Drivers!$B$21)^C5 -> 0.91533181 | D23: =1/(1+Drivers!$B$21)^D5 -> 0.83783232 | E23: =1/(1+Drivers!$B$21)^E5 -> 0.76689457 | F23: =1/(1+Drivers!$B$21)^F5 -> 0.70196299 | G23: =1/(1+Drivers!$B$21)^G5 -> 0.64252906 | H23: =1/(1+Drivers!$B$21)^H5 -> 0.58812728 | I23: =1/(1+Drivers!$B$21)^I5 -> 0.53833161 | ... K23: =1/(1+Drivers!$B$21)^K5 -> 0.45103162
A24: PV of FCFF | B24: =B22*B23 -> 720.87859 | C24: =C22*C23 -> 122.54622 | D24: =D22*D23 -> 111.47076 | E24: =E22*E23 -> 107.63423 | F24: =F22*F23 -> 91.840613 | G24: =G22*G23 -> 90.171262 | H24: =H22*H23 -> 103.97003 | I24: =I22*I23 -> 93.735063 | ... K24: =K22*K23 -> 76.519594
A25: EBITDA (SOI + D&A - corporate) | C25: =C11+C13 -> 1412.6655 | D25: =D11+D13 -> 1426.0141 | E25: =E11+E13 -> 1420.9618 | F25: =F11+F13 -> 1424.2741 | G25: =G11+G13 -> 1431.7962 | H25: =H11+H13 -> 1441.4499 | I25: =I11+I13 -> 1452.1958 | J25: =J11+J13 -> 1463.5136 | K25: =K11+K13 -> 1475.1425
A28: Terminal value (Gordon, value-driver form)
A29: Terminal growth g | B29: =Drivers!D$59 -> 0.01
A30: RONIC | B30: =Drivers!D$60 -> 0.07
A31: Revenue 2036 | B31: =K6*(1+B29) -> 19180.232
A32: Corporate cost 2036 | B32: =Drivers!$B$35*(1+Drivers!$B$36)^(2036-2026) -> 192.01268
A33: EBIT 2036 (2035 SOI margin) | B33: =B31*K8-B32 -> 575.1966
A34: NOPAT 2036 after normalized restructuring & fees | B34: =(B33-Drivers!D$58-Drivers!$B$38)*(1-Drivers!$B$42) -> 296.54942
A35: Terminal value at end-2035 | B35: =B34*(1-B29/B30)/(Drivers!$B$21-B29) -> 3081.0329
A36: PV of terminal value (t = 9.5) | B36: =B35/(1+Drivers!$B$21)^9.5 -> 1329.513
A38: Valuation
A39: Sum of PV of FCFF (H2-26 to 2035) | B39: =SUM(B24:K24) -> 1603.4379
A40: Enterprise value at 6/30/26 | B40: =B39+B36 -> 2932.9509
A41: Terminal value share of EV | B41: =B36/B40 -> 0.45330218
A42: Less: claims (net debt, pension, asbestos, minority) | B42: =Drivers!$B$31 -> 6910
A43: Equity value at 6/30/26 | B43: =B40-B42 -> -3977.0491
A44: Equity value at 9/26/26 (floored at zero) | B44: =MAX(B43,0)*Drivers!$B$22 -> 0
...

Sheet EPV
A1: Earnings power value (Greenwald) - no growth, mid-cycle margin
A3: Mid-cycle SOI margin | B3: 0.06
A4: Revenue basis ($m) | B4: 17600
A5: Normalized restructuring ($m) | B5: 100
A6: Tax rate on EPV earnings | B6: 0.23
A7: Corporate cost (2027) | B7: =Drivers!$B$35*(1+Drivers!$B$36) -> 153.75
A9: EPV at margin | B9: 5.0% | C9: 5.5% | D9: 6.0% | E9: 6.5% | F9: 7.0%
A10: SOI margin | B10: 0.05 | C10: 0.055 | D10: =B3 -> 0.06 | E10: 0.065 | F10: 0.07
A11: Normalized EBIT (after corporate, restructuring, fees) | B11: =B10*$B$4-$B$7-$B$5-Drivers!$B$38 -> 591.25 | C11: =C10*$B$4-$B$7-$B$5-Drivers!$B$38 -> 679.25 | D11: =D10*$B$4-$B$7-$B$5-Drivers!$B$38 -> 767.25 | E11: =E10*$B$4-$B$7-$B$5-Drivers!$B$38 -> 855.25 | F11: =F10*$B$4-$B$7-$B$5-Drivers!$B$38 -> 943.25
A12: NOPAT | B12: =B11*(1-$B$6) -> 455.2625 | C12: =C11*(1-$B$6) -> 523.0225 | D12: =D11*(1-$B$6) -> 590.7825 | E12: =E11*(1-$B$6) -> 658.5425 | F12: =F11*(1-$B$6) -> 726.3025
A13: EPV of operations at YE-2026 | B13: =B12/Drivers!$B$21 -> 4921.7568 | C13: =C12/Drivers!$B$21 -> 5654.2973 | D13: =D12/Drivers!$B$21 -> 6386.8378 | E13: =E12/Drivers!$B$21 -> 7119.3784 | F13: =F12/Drivers!$B$21 -> 7851.9189
A14: EV at 6/30/26 (incl. base H2-26 FCFF) | B14: =B13/(1+Drivers!$B$21)^0.5+Drivers!$C$53/(1+Drivers!$B$21)^0.25 -> 5551.9354 | C14: =C13/(1+Drivers!$B$21)^0.5+Drivers!$C$53/(1+Drivers!$B$21)^0.25 -> 6252.7787 | D14: =D13/(1+Drivers!$B$21)^0.5+Drivers!$C$53/(1+Drivers!$B$21)^0.25 -> 6953.622 | E14: =E13/(1+Drivers!$B$21)^0.5+Drivers!$C$53/(1+Drivers!$B$21)^0.25 -> 7654.4654 | F14: =F13/(1+Drivers!$B$21)^0.5+Drivers!$C$53/(1+Drivers!$B$21)^0.25 -> 8355.3087
A15: Equity value 6/30/26 | B15: =B14-Drivers!$B$31 -> -1358.0646 | C15: =C14-Drivers!$B$31 -> -657.22129 | D15: =D14-Drivers!$B$31 -> 43.622038 | E15: =E14-Drivers!$B$31 -> 744.46536 | F15: =F14-Drivers!$B$31 -> 1445.3087
A16: EPV per share ($) | B16: =MAX(B15,0)*Drivers!$B$22/Drivers!$B$5 -> 0 | C16: =MAX(C15,0)*Drivers!$B$22/Drivers!$B$5 -> 0 | D16: =MAX(D15,0)*Drivers!$B$22/Drivers!$B$5 -> 0.15447708 | E16: =MAX(E15,0)*Drivers!$B$22/Drivers!$B$5 -> 2.6363471 | F16: =MAX(F15,0)*Drivers!$B$22/Drivers!$B$5 -> 5.1182171
A18: Growth value in base DCF (EV_base - EPV EV at mid-cycle margin) | B18: =DCF_Base!B40-D14 -> 521.64929

Sheet Merton
A1: Merton structural model - equity as a call on enterprise value
A3: Probability-weighted EV ($m) | B3: =Drivers!B52*DCF_Bull!B40+Drivers!C52*DCF_Base!B40+Drivers!D52*DCF_Bear!B40+Drivers!B62*0.9*DCF_Bear!B40 -> 6260.4641
A4: Asset value V = EV + cash | B4: =B3+Drivers!B26 -> 7121.4641
A5: Claims K (debt + pension + asbestos + minority) | B5: =Drivers!B25+Drivers!B28+Drivers!B29+Drivers!B30 -> 7771
A6: Average cost of debt (carry on face) | B6: 0.063
A7: Risk-free rate (5y) | B7: 0.047
A8: Asset volatility | B8: 0.22
A9: Horizon T (years) | B9: 5
A10: Face value at T | B10: =B5*EXP((B6-B7)*B9) -> 8418.2238
A11: d1 | B11: =(LN(B4/B10)+(B7+0.5*B8^2)*B9)/(B8*SQRT(B9)) -> 0.38361673
A12: d2 | B12: =B11-B8*SQRT(B9) -> -0.10831822
A13: Equity value (call) | B13: =B4*NORMSDIST(B11)-B10*EXP(-B7*B9)*NORMSDIST(B12) -> 1583.8829
A14: Equity value per share ($) | B14: =B13*Drivers!B22/Drivers!B5 -> 5.6089449
A15: Risk-neutral probability equity finishes worthless | B15: =NORMSDIST(-B12) -> 0.54312837
A17: Same model on bear / base / bull EV
B18: Bear | C18: Base | D18: Bull
A19: Asset value V | B19: =DCF_Bear!B40+Drivers!$B$26 -> 3793.9509 | C19: =DCF_Base!B40+Drivers!$B$26 -> 8336.2713 | D19: =DCF_Bull!B40+Drivers!$B$26 -> 12585.047
A20: d1 | B20: =(LN(B19/$B$10)+($B$7+0.5*$B$8^2)*$B$9)/($B$8*SQRT($B$9)) -> -0.89644153 | C20: =(LN(C19/$B$10)+($B$7+0.5*$B$8^2)*$B$9)/($B$8*SQRT($B$9)) -> 0.70378649 | D20: =(LN(D19/$B$10)+($B$7+0.5*$B$8^2)*$B$9)/($B$8*SQRT($B$9)) -> 1.5410788
A21: Equity per share ($) | B21: =(B19*NORMSDIST(B20)-$B$10*EXP(-$B$7*$B$9)*NORMSDIST(B20-$B$8*SQRT($B$9)))*Drivers!$B$22/Drivers!$B$5 -> 0.54104933 | C21: =(C19*NORMSDIST(C20)-$B$10*EXP(-$B$7*$B$9)*NORMSDIST(C20-$B$8*SQRT($B$9)))*Drivers!$B$22/Drivers!$B$5 -> 8.6518114 | D21: =(D19*NORMSDIST(D20)-$B$10*EXP(-$B$7*$B$9)*NORMSDIST(D20-$B$8*SQRT($B$9)))*Drivers!$B$22/Drivers!$B$5 -> 21.717424

Sheet Comps
A1: Peer multiples (Yahoo Finance fundamentals, prices 2026-09-25; local currency)
A3: Company | B3: Role | C3: EV/Sales | D3: EV/EBITDA | E3: EV/EBIT | F3: P/E | G3: P/B | H3: EBITDA margin | I3: Op. margin | J3: 4y avg op. margin | K3: Net debt/EBITDA | L3: Note
A4: Michelin | B4: core | C4: 1.0757163 | D4: 5.6049559 | E4: 9.9866804 | F4: 14.414221 | G4: 1.3082133 | H4: 0.19192234 | I4: 0.1077151 | J4: 0.11230358 | K4: 0.95124924 | L4: Global premium leader; ~11% segment margin; strong balance sheet
A5: Bridgestone | B5: core | C5: 1.0689202 | D5: 5.6341979 | E5: 9.9683795 | F5: 11.480598 | G5: 1.2689861 | H5: 0.18972003 | I5: 0.10723109 | J5: 0.10129774 | K5: 0.11167621 | L5: Global #1-2; premium; net cash-ish
A6: Continental (post-spin) | B6: core | C6: 1.0564131 | D6: 5.8152173 | E6: 11.596507 | G6: 3.2842486 | H6: 0.18166357 | I6: 0.091097529 | J6: 0.047426672 | K6: 1.7238151 | L6: Tires + ContiTech after Aumovio spin (Sep-2025)
A7: Pirelli | B7: core | C7: 1.3692266 | D7: 6.1921469 | E7: 12.893532 | F7: 13.41213 | G7: 1.0990277 | H7: 0.22112308 | I7: 0.10619484 | J7: 0.095187416 | K7: 1.3603761 | L7: High-value premium niche; highest margins
A8: Yokohama Rubber | B8: core | C8: 1.2070526 | D8: 5.0433589 | E8: 7.5252968 | F8: 7.7366994 | G8: 0.98025931 | H8: 0.23933506 | I8: 0.16039933 | J8: 0.10362844 | K8: 1.4590033 | L8: Mid-tier + OTR (bought GT OTR 2025, TWS 2023)
A9: Toyo Tire | B9: core | C9: 0.91476257 | D9: 4.056356 | E9: 6.2873027 | F9: 9.9829338 | G9: 1.0842549 | H9: 0.22551339 | I9: 0.14549364 | J9: 0.13938875 | K9: -0.38152733 | L9: Mid-tier, US-heavy light-truck/SUV exposure
A10: Sumitomo Rubber | B10: core | C10: 0.63961054 | D10: 4.402534 | E10: 9.6834465 | F10: 4.038155 | G10: 0.70952727 | H10: 0.14528236 | I10: 0.066051952 | J10: 0.041354069 | K10: 1.354151 | L10: Closest structural analogue: mid-tier, low margin; bought Dunlop brand from GT; TTM series truncated on source; revenue/EBITDA from quoteSummary, EBIT/NI scaled
A11: Kumho Tire | B11: core | C11: 0.70772204 | D11: 3.5267892 | E11: 5.7882892 | F11: 3.9602292 | G11: 0.77907829 | H11: 0.20067035 | I11: 0.12226791 | J11: 0.090297923 | K11: 1.3030319 | L11: Low-cost Korean; leveraged
A12: Nokian Tyres | B12: reference | C12: 2.1261892 | D12: 14.445879 | E12: 40.855056 | F12: 113.03019 | G12: 1.9427841 | H12: 0.1471831 | I12: 0.052042254 | J12: 0.023797192 | K12: 3.9 | L12: Post-Russia rebuild; multiple inflated by recovery / depressed EBITDA
A13: Hankook Tire & Tech | B13: reference | C13: 0.58229441 | D13: 4.7934285 | E13: 5.7903629 | F13: 5.7627277 | G13: 0.5210098 | H13: 0.12147765 | I13: 0.10056268 | J13: 0.12667508 | K13: 1.319908 | L13: Consolidates Hanon Systems (auto thermal) from 2025 -> not pure tire
A14: Apollo Tyres | B14: excluded | C14: 0.95966381 | D14: 6.4289757 | E14: 10.490639 | F14: 14.814699 | G14: 1.5141685 | H14: 0.14927165 | I14: 0.091478106 | J14: 0.093728763 | K14: 0.59265617 | L14: India-centric growth market
A15: Sailun | B15: excluded | C15: 1.4191777 | D15: 8.0284263 | E15: 10.141615 | F15: 11.576614 | G15: 1.967424 | H15: 0.1767691 | I15: 0.13993607 | J15: 0.13474425 | K15: 1.3461782 | L15: Chinese low-cost exporter (share taker vs GT), high growth
A16: Linglong | B16: excluded | C16: 0.98378813 | D16: 7.8420201 | E16: 14.898629 | F16: 24.738054 | G16: 0.67610295 | H16: 0.12545086 | I16: 0.066032123 | J16: 0.079423753 | K16: 3.0888022 | L16: Chinese low-cost exporter
A17: Goodyear (LTM Jun-26, IFRS-like) | B17: subject | C17: 0.50811055 | D17: 4.5704118 | E17: 13.338279 | G17: 0.51990137 | H17: 0.11117391 | I17: 0.038094162 | J17: 0.050583757 | K17: 3.7376716 | L17: Company data LTM Jun-26; leases capitalised for comparability
A19: Core peer statistics
A20: Statistic | C20: EV/Sales | D20: EV/EBITDA | E20: EV/EBIT | F20: P/E | G20: P/B
A21: 25th percentile | C21: =QUARTILE(C4:C11,1) -> 0.86300244 | D21: =QUARTILE(D4:D11,1) -> 4.3159895 | E21: =QUARTILE(E4:E11,1) -> 7.2157982 | F21: =QUARTILE(F4:F11,1) -> 5.8874272 | G21: =QUARTILE(G4:G11,1) -> 0.92996406
A22: Median | C22: =MEDIAN(C4:C11) -> 1.0626667 | D22: =MEDIAN(D4:D11) -> 5.3241574 | E22: =MEDIAN(E4:E11) -> 9.825913 | F22: =MEDIAN(F4:F11) -> 9.9829338 | G22: =MEDIAN(G4:G11) -> 1.0916413
A23: 75th percentile | C23: =QUARTILE(C4:C11,3) -> 1.1085503 | D23: =QUARTILE(D4:D11,3) -> 5.6794528 | E23: =QUARTILE(E4:E11,3) -> 10.389137 | F23: =QUARTILE(F4:F11,3) -> 12.446364 | G23: =QUARTILE(G4:G11,3) -> 1.2787929
A24: Min | C24: =MIN(C4:C11) -> 0.63961054 | D24: =MIN(D4:D11) -> 3.5267892 | E24: =MIN(E4:E11) -> 5.7882892 | F24: =MIN(F4:F11) -> 3.9602292 | G24: =MIN(G4:G11) -> 0.70952727
A25: Max | C25: =MAX(C4:C11) -> 1.3692266 | D25: =MAX(D4:D11) -> 6.1921469 | E25: =MAX(E4:E11) -> 12.893532 | F25: =MAX(F4:F11) -> 14.414221 | G25: =MAX(G4:G11) -> 3.2842486
A28: Applying multiples to GT 2027E (base case)
A29: 2027E EBITDA, US GAAP ($m) | B29: =DCF_Base!C25 -> 1636.2
A30: Operating lease cost add-back ($m) | B30: 318
A31: 2027E EBITDA, IFRS-like ($m) | B31: =B29+B30 -> 1954.2
A32: Operating lease liabilities ($m) | B32: 1023
A33: 2027E EBIT (SOI - corporate) ($m) | B33: =DCF_Base!C11 -> 736.2
A34: Claims at YE-2026E (6/30 claims less base H2 levered FCF) | B34: =Drivers!B31-(Drivers!C53-Drivers!B44) -> 6273
A35: GT own EV/adj. EBITDA median 2022-2025 | B35: 4.5
A37: Method | B37: Multiple | C37: Metric ($m) | D37: EV ($m) | E37: Equity/share ($)
A38: Peer EV/EBITDA - 25th pct | B38: =D21 -> 4.3159895 | C38: =B31 -> 1954.2 | D38: =B38*C38-B32 -> 7411.3066 | E38: =MAX(D38-$B$34,0)/(1+Drivers!$B$21)^0.26*Drivers!$B$22/Drivers!$B$5 -> 3.9393791
A39: Peer EV/EBITDA - median | B39: =D22 -> 5.3241574 | C39: =B31 -> 1954.2 | D39: =B39*C39-B32 -> 9381.4683 | E39: =MAX(D39-$B$34,0)/(1+Drivers!$B$21)^0.26*Drivers!$B$22/Drivers!$B$5 -> 10.757589
A40: Peer EV/EBITDA - 75th pct | B40: =D23 -> 5.6794528 | C40: =B31 -> 1954.2 | D40: =B40*C40-B32 -> 10075.787 | E40: =MAX(D40-$B$34,0)/(1+Drivers!$B$21)^0.26*Drivers!$B$22/Drivers!$B$5 -> 13.160442
A41: Peer EV/EBIT - 25th pct | B41: =E21 -> 7.2157982 | C41: =B33 -> 736.2 | D41: =B41*C41 -> 5312.2707 | E41: =MAX(D41-$B$34,0)/(1+Drivers!$B$21)^0.26*Drivers!$B$22/Drivers!$B$5 -> 0
A42: Peer EV/EBIT - median | B42: =E22 -> 9.825913 | C42: =B33 -> 736.2 | D42: =B42*C42 -> 7233.8371 | E42: =MAX(D42-$B$34,0)/(1+Drivers!$B$21)^0.26*Drivers!$B$22/Drivers!$B$5 -> 3.325204
A43: Peer EV/EBIT - 75th pct | B43: =E23 -> 10.389137 | C43: =B33 -> 736.2 | D43: =B43*C43 -> 7648.4827 | E43: =MAX(D43-$B$34,0)/(1+Drivers!$B$21)^0.26*Drivers!$B$22/Drivers!$B$5 -> 4.7601829
A44: GT own-history EV/EBITDA (US GAAP) | B44: =B35 -> 4.5 | C44: =B29 -> 1636.2 | D44: =B44*C44 -> 7362.9 | E44: =MAX(D44-$B$34,0)/(1+Drivers!$B$21)^0.26*Drivers!$B$22/Drivers!$B$5 -> 3.7718565
A45: Comps central value (avg of peer EV/EBITDA median, peer EV/EBIT median, own history) | E45: =AVERAGE(E39,E42,E44) -> 5.95155
...

Sheet SOTP
A1: Sum of the parts - mid-cycle segment economics
A3: Segment | B3: Revenue ($m) | C3: SOI margin | D3: SOI ($m) | E3: D&A ($m) | F3: EBITDA ($m) | G3: EV/EBITDA | H3: Value ($m)
A4: Americas | B4: 10300 | C4: 0.07 | D4: =B4*C4 -> 721 | E4: 480 | F4: =D4+E4 -> 1201 | G4: 5 | H4: =F4*G4 -> 6005
A5: Europe, Middle East & Africa | B5: 5700 | C5: 0.025 | D5: =B5*C5 -> 142.5 | E5: 290 | F5: =D5+E5 -> 432.5 | G5: 4 | H5: =F5*G5 -> 1730
A6: Asia Pacific | B6: 1950 | C6: 0.12 | D6: =B6*C6 -> 234 | E6: 130 | F6: =D6+E6 -> 364 | G6: 6.5 | H6: =F6*G6 -> 2366
A8: Corporate cost ($m) x multiple | B8: 155 | G8: 5.5 | H8: =-B8*G8 -> -852.5
A9: PV of restructuring cash 2027-2029 | H9: -450
A10: EV at mid-cycle | H10: =SUM(H4:H9) -> 8798.5
A11: Years until mid-cycle | B11: 1.5
A12: EV at 6/30/26 (discounted + H2-26 FCFF + half of 2027 FCFF) | H12: =H10/(1+Drivers!B21)^B11+Drivers!C53/(1+Drivers!B21)^0.25+DCF_Base!C22/(1+Drivers!B21)*0.5 -> 8698.0131
A13: Equity value 6/30/26 | H13: =H12-Drivers!B31 -> 1788.0131
A14: SOTP value per share ($) | H14: =MAX(H13,0)*Drivers!B22/Drivers!B5 -> 6.3318233
A15: Total mid-cycle SOI margin | H15: =SUM(D4:D6)/SUM(B4:B6) -> 0.061142061

Sheet Transactions_Asset
A1: Precedent transactions (control) and asset-based references
A3: Transaction | B3: Multiple | C3: Basis / note
A4: Goodyear / Cooper Tire (2021) | B4: 6.4 | C4: EV ~$2.5bn (equity $2.8bn at $54.36/sh less net cash ~$0.3bn) / 2020 EBITDA $390m (op. income 231 + D&A 159, SEC XBRL) (EV/EBITDA)
A5: GT OTR -> Yokohama (2025) | B5: 7.2 | C5: $905m / est. EBITDA ~$125m (analyst estimate; segment disclosure only) (EV/EBITDA)
A6: GT Chemical -> Gemspring (2025) | B6: 4.3 | C6: $650m / est. EBITDA ~$150m (SOI impact ~$120m + D&A ~$30m) (EV/EBITDA)
A7: GT Dunlop brand -> Sumitomo Rubber (2025) | B7: 9.7 | C7: $631m (brand + transition fee) / $65m annual SOI impact (EV/SOI)
A9: Control multiple applied (EV/EBITDA) | B9: 6
A10: Base 2030E EBITDA ($m) | B10: =DCF_Base!F25 -> 1857.7906
A11: Control EV at 6/30/26 (discounted 3.5 yrs) | B11: =B9*B10/(1+Drivers!B21)^3.5 -> 8178.4867
A12: Control value per share ($) | B12: =MAX(B11-Drivers!B31,0)*Drivers!B22/Drivers!B5 -> 4.4920441
A13: Minority discount | B13: 0.2
A14: Minority value per share ($) | B14: =MAX(B11*(1-B13)-Drivers!B31,0)*Drivers!B22/Drivers!B5 -> 0
A17: Asset-based
A18: Asset (6/30/26, $m) | B18: Book | C18: Recovery % | D18: Liquidation value
A19: Accounts receivable | B19: 2728 | C19: 0.85 | D19: =B19*C19 -> 2318.8
A20: Inventories | B20: 3916 | C20: 0.55 | D20: =B20*C20 -> 2153.8
A21: PP&E | B21: 7598 | C21: 0.2 | D21: =B21*C21 -> 1519.6
A22: Other assets | B22: 1528 | C22: 0.25 | D22: =B22*C22 -> 382
A23: Brands (Goodyear, Cooper) - estimate | B23: 2000 | C23: 1 | D23: =B23*C23 -> 2000
A24: Total liquidation proceeds | D24: =SUM(D19:D23) -> 8374.2
A25: Total liabilities (10-Q Q2-26) | D25: 15649
A26: Liquidation value to equity | D26: =D24-D25 -> -7274.8
A27: Liquidation value per share ($) | D27: =MAX(D26,0)/288 -> 0
A28: Book equity per share ($) | D28: =2839/288 -> 9.8576389
A29: Tangible book per share ($) (ex goodwill 44, intangibles 651) | D29: =(2839-44-651)/288 -> 7.4444444

Sheet MonteCarlo
A1: Monte Carlo (static output of scripts/valuation_engine.py, 20,000 draws, seed 42)
A3: Distribution of value per share ($) | D3: Input distributions
A4: mean | B4: 3.194 | D4: Long-run SOI margin ~ N(mean, sd), truncated | G4: 5.7% / 1.4% [1%-10%]
A5: P5 | B5: 0 | D5: 2026E SOI ~ N | G5: $570m / $45m
A6: P10 | B6: 0 | D6: Years to reach long-run margin ~ U{2,3,4}
A7: P25 | B7: 0 | D7: Revenue growth 2027-35 ~ N (corr 0.4 with margin) | G7: 2.0% / 1.0%
A8: P50 | B8: 0 | D8: Capex % revenue ~ N | G8: 4.6% / 0.3%
A9: P75 | B9: 4.9773 | D9: Restructuring $m/yr ~ U | G9: 60-160
A10: P90 | B10: 10.8603 | D10: WACC ~ N (clipped 7-12%) | G10: 9.25% / 0.60%
A11: P95 | B11: 14.5764 | D11: Terminal growth ~ U | G11: 0.5%-2.0%
A12: P(value > price) | B12: 0.2444 | D12: RONIC = WACC + N(0, sd) | G12: sd 1.5%
A13: P(equity worthless or distress) | B13: 0.5624 | D13: Terminal tax ~ U | G13: 21%-26%
D14: Distress trigger | G14: net debt/EBITDA > 6.0x in 2027-28 -> $0.2/sh
A15: Driver rank correlation with value
A16: long_run_margin | B16: 0.787
A17: revenue_growth | B17: 0.426
A18: wacc | B18: -0.155
A19: terminal_growth | B19: 0.006
A20: capex_pct | B20: -0.004
A21: restructuring | B21: -0.055
A22: ronic_spread | B22: 0.036
A23: soi_2026 | B23: 0.019
A24: recovery_years | B24: -0.059
A28: Histogram (value per share, $0.50 bins, clipped at $30)
A29: Bin start ($) | B29: Draws
A30: 0 | B30: 11506
A31: 0.5 | B31: 394
A32: 1 | B32: 439
A33: 1.5 | B33: 385
A34: 2 | B34: 406
A35: 2.5 | B35: 412
A36: 3 | B36: 358
A37: 3.5 | B37: 400
A38: 4 | B38: 372
A39: 4.5 | B39: 349
A40: 5 | B40: 323
A41: 5.5 | B41: 305
... A89: 29.5 | B89: 23

Sheet Sensitivity
A1: Sensitivity of base-case value per share ($)
A3: WACC (rows) x terminal growth (columns) - live formulas on DCF_Base cash flows (RONIC = WACC)
A4: WACC \ g | B4: 0.005 | C4: 0.01 | D4: 0.015 | E4: 0.02 | F4: 0.025
A5: 0.0825 | B5: =MAX(SUMPRODUCT(DCF_Base!$B$22:$K$22,1/(1+$A5)^DCF_Base!$B$5:$K$5)+((DCF_Base!$K$6*(1+B$4)*DCF_Base!$K$8-DCF_Base!$B$32-Drivers!$C$58-Drivers!$B$38)*(1-Drivers!$B$42))*(1-B$4/$A5)/($A5-B$4)/(1+$A5)^9.5-Drivers!$B$31,0)*Drivers!$B$22/Drivers!$B$5 -> 5.054499 | C5: =MAX(SUMPRODUCT(DCF_Base!$B$22:$K$22,1/(1+$A5)^DCF_Base!$B$5:$K$5)+((DCF_Base!$K$6*(1+C$4)*DCF_Base!$K$8-DCF_Base!$B$32-Drivers!$C$58-Drivers!$B$38)*(1-Drivers!$B$42))*(1-C$4/$A5)/($A5-C$4)/(1+$A5)^9.5-Drivers!$B$31,0)*Drivers!$B$22/Drivers!$B$5 -> 5.1525079 | D5: =MAX(SUMPRODUCT(DCF_Base!$B$22:$K$22,1/(1+$A5)^DCF_Base!$B$5:$K$5)+((DCF_Base!$K$6*(1+D$4)*DCF_Base!$K$8-DCF_Base!$B$32-Drivers!$C$58-Drivers!$B$38)*(1-Drivers!$B$42))*(1-D$4/$A5)/($A5-D$4)/(1+$A5)^9.5-Drivers!$B$31,0)*Drivers!$B$22/Drivers!$B$5 -> 5.2505168 | E5: =MAX(SUMPRODUCT(DCF_Base!$B$22:$K$22,1/(1+$A5)^DCF_Base!$B$5:$K$5)+((DCF_Base!$K$6*(1+E$4)*DCF_Base!$K$8-DCF_Base!$B$32-Drivers!$C$58-Drivers!$B$38)*(1-Drivers!$B$42))*(1-E$4/$A5)/($A5-E$4)/(1+$A5)^9.5-Drivers!$B$31,0)*Drivers!$B$22/Drivers!$B$5 -> 5.3485257 | F5: =MAX(SUMPRODUCT(DCF_Base!$B$22:$K$22,1/(1+$A5)^DCF_Base!$B$5:$K$5)+((DCF_Base!$K$6*(1+F$4)*DCF_Base!$K$8-DCF_Base!$B$32-Drivers!$C$58-Drivers!$B$38)*(1-Drivers!$B$42))*(1-F$4/$A5)/($A5-F$4)/(1+$A5)^9.5-Drivers!$B$31,0)*Drivers!$B$22/Drivers!$B$5 -> 5.4465347
A6: 0.0875 | B6: =MAX(SUMPRODUCT(DCF_Base!$B$22:$K$22,1/(1+$A6)^DCF_Base!$B$5:$K$5)+((DCF_Base!$K$6*(1+B$4)*DCF_Base!$K$8-DCF_Base!$B$32-Drivers!$C$58-Drivers!$B$38)*(1-Drivers!$B$42))*(1-B$4/$A6)/($A6-B$4)/(1+$A6)^9.5-Drivers!$B$31,0)*Drivers!$B$22/Drivers!$B$5 -> 3.3531246 | C6: =MAX(SUMPRODUCT(DCF_Base!$B$22:$K$22,1/(1+$A6)^DCF_Base!$B$5:$K$5)+((DCF_Base!$K$6*(1+C$4)*DCF_Base!$K$8-DCF_Base!$B$32-Drivers!$C$58-Drivers!$B$38)*(1-Drivers!$B$42))*(1-C$4/$A6)/($A6-C$4)/(1+$A6)^9.5-Drivers!$B$31,0)*Drivers!$B$22/Drivers!$B$5 -> 3.4415748 | D6: =MAX(SUMPRODUCT(DCF_Base!$B$22:$K$22,1/(1+$A6)^DCF_Base!$B$5:$K$5)+((DCF_Base!$K$6*(1+D$4)*DCF_Base!$K$8-DCF_Base!$B$32-Drivers!$C$58-Drivers!$B$38)*(1-Drivers!$B$42))*(1-D$4/$A6)/($A6-D$4)/(1+$A6)^9.5-Drivers!$B$31,0)*Drivers!$B$22/Drivers!$B$5 -> 3.5300249 | E6: =MAX(SUMPRODUCT(DCF_Base!$B$22:$K$22,1/(1+$A6)^DCF_Base!$B$5:$K$5)+((DCF_Base!$K$6*(1+E$4)*DCF_Base!$K$8-DCF_Base!$B$32-Drivers!$C$58-Drivers!$B$38)*(1-Drivers!$B$42))*(1-E$4/$A6)/($A6-E$4)/(1+$A6)^9.5-Drivers!$B$31,0)*Drivers!$B$22/Drivers!$B$5 -> 3.6184751 | F6: =MAX(SUMPRODUCT(DCF_Base!$B$22:$K$22,1/(1+$A6)^DCF_Base!$B$5:$K$5)+((DCF_Base!$K$6*(1+F$4)*DCF_Base!$K$8-DCF_Base!$B$32-Drivers!$C$58-Drivers!$B$38)*(1-Drivers!$B$42))*(1-F$4/$A6)/($A6-F$4)/(1+$A6)^9.5-Drivers!$B$31,0)*Drivers!$B$22/Drivers!$B$5 -> 3.7069253
A7: 0.0925 | B7: =MAX(SUMPRODUCT(DCF_Base!$B$22:$K$22,1/(1+$A7)^DCF_Base!$B$5:$K$5)+((DCF_Base!$K$6*(1+B$4)*DCF_Base!$K$8-DCF_Base!$B$32-Drivers!$C$58-Drivers!$B$38)*(1-Drivers!$B$42))*(1-B$4/$A7)/($A7-B$4)/(1+$A7)^9.5-Drivers!$B$31,0)*Drivers!$B$22/Drivers!$B$5 -> 1.8415715 | C7: =MAX(SUMPRODUCT(DCF_Base!$B$22:$K$22,1/(1+$A7)^DCF_Base!$B$5:$K$5)+((DCF_Base!$K$6*(1+C$4)*DCF_Base!$K$8-DCF_Base!$B$32-Drivers!$C$58-Drivers!$B$38)*(1-Drivers!$B$42))*(1-C$4/$A7)/($A7-C$4)/(1+$A7)^9.5-Drivers!$B$31,0)*Drivers!$B$22/Drivers!$B$5 -> 1.9216728 | D7: =MAX(SUMPRODUCT(DCF_Base!$B$22:$K$22,1/(1+$A7)^DCF_Base!$B$5:$K$5)+((DCF_Base!$K$6*(1+D$4)*DCF_Base!$K$8-DCF_Base!$B$32-Drivers!$C$58-Drivers!$B$38)*(1-Drivers!$B$42))*(1-D$4/$A7)/($A7-D$4)/(1+$A7)^9.5-Drivers!$B$31,0)*Drivers!$B$22/Drivers!$B$5 -> 2.001774 | E7: =MAX(SUMPRODUCT(DCF_Base!$B$22:$K$22,1/(1+$A7)^DCF_Base!$B$5:$K$5)+((DCF_Base!$K$6*(1+E$4)*DCF_Base!$K$8-DCF_Base!$B$32-Drivers!$C$58-Drivers!$B$38)*(1-Drivers!$B$42))*(1-E$4/$A7)/($A7-E$4)/(1+$A7)^9.5-Drivers!$B$31,0)*Drivers!$B$22/Drivers!$B$5 -> 2.0818752 | F7: =MAX(SUMPRODUCT(DCF_Base!$B$22:$K$22,1/(1+$A7)^DCF_Base!$B$5:$K$5)+((DCF_Base!$K$6*(1+F$4)*DCF_Base!$K$8-DCF_Base!$B$32-Drivers!$C$58-Drivers!$B$38)*(1-Drivers!$B$42))*(1-F$4/$A7)/($A7-F$4)/(1+$A7)^9.5-Drivers!$B$31,0)*Drivers!$B$22/Drivers!$B$5 -> 2.1619765
A8: 0.0975 | B8: =MAX(SUMPRODUCT(DCF_Base!$B$22:$K$22,1/(1+$A8)^DCF_Base!$B$5:$K$5)+((DCF_Base!$K$6*(1+B$4)*DCF_Base!$K$8-DCF_Base!$B$32-Drivers!$C$58-Drivers!$B$38)*(1-Drivers!$B$42))*(1-B$4/$A8)/($A8-B$4)/(1+$A8)^9.5-Drivers!$B$31,0)*Drivers!$B$22/Drivers!$B$5 -> 0.49033692 | C8: =MAX(SUMPRODUCT(DCF_Base!$B$22:$K$22,1/(1+$A8)^DCF_Base!$B$5:$K$5)+((DCF_Base!$K$6*(1+C$4)*DCF_Base!$K$8-DCF_Base!$B$32-Drivers!$C$58-Drivers!$B$38)*(1-Drivers!$B$42))*(1-C$4/$A8)/($A8-C$4)/(1+$A8)^9.5-Drivers!$B$31,0)*Drivers!$B$22/Drivers!$B$5 -> 0.56310435 | D8: =MAX(SUMPRODUCT(DCF_Base!$B$22:$K$22,1/(1+$A8)^DCF_Base!$B$5:$K$5)+((DCF_Base!$K$6*(1+D$4)*DCF_Base!$K$8-DCF_Base!$B$32-Drivers!$C$58-Drivers!$B$38)*(1-Drivers!$B$42))*(1-D$4/$A8)/($A8-D$4)/(1+$A8)^9.5-Drivers!$B$31,0)*Drivers!$B$22/Drivers!$B$5 -> 0.63587178 | E8: =MAX(SUMPRODUCT(DCF_Base!$B$22:$K$22,1/(1+$A8)^DCF_Base!$B$5:$K$5)+((DCF_Base!$K$6*(1+E$4)*DCF_Base!$K$8-DCF_Base!$B$32-Drivers!$C$58-Drivers!$B$38)*(1-Drivers!$B$42))*(1-E$4/$A8)/($A8-E$4)/(1+$A8)^9.5-Drivers!$B$31,0)*Drivers!$B$22/Drivers!$B$5 -> 0.70863921 | F8: =MAX(SUMPRODUCT(DCF_Base!$B$22:$K$22,1/(1+$A8)^DCF_Base!$B$5:$K$5)+((DCF_Base!$K$6*(1+F$4)*DCF_Base!$K$8-DCF_Base!$B$32-Drivers!$C$58-Drivers!$B$38)*(1-Drivers!$B$42))*(1-F$4/$A8)/($A8-F$4)/(1+$A8)^9.5-Drivers!$B$31,0)*Drivers!$B$22/Drivers!$B$5 -> 0.78140665
A9: 0.1025 | B9: =MAX(SUMPRODUCT(DCF_Base!$B$22:$K$22,1/(1+$A9)^DCF_Base!$B$5:$K$5)+((DCF_Base!$K$6*(1+B$4)*DCF_Base!$K$8-DCF_Base!$B$32-Drivers!$C$58-Drivers!$B$38)*(1-Drivers!$B$42))*(1-B$4/$A9)/($A9-B$4)/(1+$A9)^9.5-Drivers!$B$31,0)*Drivers!$B$22/Drivers!$B$5 -> 0 | C9: =MAX(SUMPRODUCT(DCF_Base!$B$22:$K$22,1/(1+$A9)^DCF_Base!$B$5:$K$5)+((DCF_Base!$K$6*(1+C$4)*DCF_Base!$K$8-DCF_Base!$B$32-Drivers!$C$58-Drivers!$B$38)*(1-Drivers!$B$42))*(1-C$4/$A9)/($A9-C$4)/(1+$A9)^9.5-Drivers!$B$31,0)*Drivers!$B$22/Drivers!$B$5 -> 0 | D9: =MAX(SUMPRODUCT(DCF_Base!$B$22:$K$22,1/(1+$A9)^DCF_Base!$B$5:$K$5)+((DCF_Base!$K$6*(1+D$4)*DCF_Base!$K$8-DCF_Base!$B$32-Drivers!$C$58-Drivers!$B$38)*(1-Drivers!$B$42))*(1-D$4/$A9)/($A9-D$4)/(1+$A9)^9.5-Drivers!$B$31,0)*Drivers!$B$22/Drivers!$B$5 -> 0 | E9: =MAX(SUMPRODUCT(DCF_Base!$B$22:$K$22,1/(1+$A9)^DCF_Base!$B$5:$K$5)+((DCF_Base!$K$6*(1+E$4)*DCF_Base!$K$8-DCF_Base!$B$32-Drivers!$C$58-Drivers!$B$38)*(1-Drivers!$B$42))*(1-E$4/$A9)/($A9-E$4)/(1+$A9)^9.5-Drivers!$B$31,0)*Drivers!$B$22/Drivers!$B$5 -> 0 | F9: =MAX(SUMPRODUCT(DCF_Base!$B$22:$K$22,1/(1+$A9)^DCF_Base!$B$5:$K$5)+((DCF_Base!$K$6*(1+F$4)*DCF_Base!$K$8-DCF_Base!$B$32-Drivers!$C$58-Drivers!$B$38)*(1-Drivers!$B$42))*(1-F$4/$A9)/($A9-F$4)/(1+$A9)^9.5-Drivers!$B$31,0)*Drivers!$B$22/Drivers!$B$5 -> 0
A12: Long-run SOI margin (3-year linear recovery from 2026E 3.3%) - static engine output
A13: Long-run SOI margin | B13: 0.04 | C13: 0.045 | D13: 0.05 | E13: 0.055 | F13: 0.06 | G13: 0.065 | H13: 0.07 | I13: 0.075 | J13: 0.08 | K13: 0.09 | L13: 0.1
A14: Value per share ($) | B14: 0 | C14: 0 | D14: 0 | E14: 0 | F14: 1.2917 | G14: 4.0783 | H14: 6.8648 | I14: 9.6513 | J14: 12.4135 | K14: 17.9143 | L14: 23.4152
A17: Tornado (base case, one variable at a time) - static engine output
A18: Driver (low / high) | B18: Low case $ | C18: High case $
A19: Long-run SOI margin 5.0% / 7.0% | B19: 0 | C19: 6.8648
A20: WACC 10.25% / 8.25% | B20: 0 | C20: 5.2505
A21: Capex 5.0% / 4.2% of sales | B21: 1.781 | C21: 2.2226
A22: Terminal growth 0.5% / 2.5% | B22: 1.8416 | C22: 2.162
A23: Revenue growth -1pt / +1pt p.a. | B23: 0.3608 | C23: 3.6913
A24: Restructuring $150m / $50m p.a. | B24: 0.7288 | C24: 3.2119
A25: H2-26 FCFF $737m / $962m | B25: 1.5688 | C25: 2.3482
A26: Terminal tax 27% / 21% | B26: 1.3752 | C26: 2.6283

Sheet History
A1: Normalized 10-year history ($m) - SEC XBRL (latest-filed values) + 10-K segment notes
A3: Metric | B3: 2015 | C3: 2016 | D3: 2017 | E3: 2018 | F3: 2019 | G3: 2020 | H3: 2021 | I3: 2022 | J3: 2023 | K3: 2024 | L3: 2025
A4: revenue | B4: 16443 | C4: 15158 | D4: 15377 | E4: 15475 | F4: 14745 | G4: 12321 | H4: 17478 | I4: 20805 | J4: 20066 | K4: 18878 | L4: 18280
A5: units_m | B5: 166.2 | C5: 166.1 | D5: 159.2 | E5: 159.2 | F5: 155.3 | G5: 126 | H5: 169.3 | I5: 184.5 | J5: 173.3 | K5: 166.6 | L5: 158.7
A6: rev_per_unit | B6: 98.9 | C6: 91.3 | D6: 96.6 | E6: 97.2 | F6: 94.9 | G6: 97.8 | H6: 103.2 | I6: 112.8 | J6: 115.8 | K6: 113.3 | L6: 115.2
A7: soi | B7: 2020 | C7: 1996 | D7: 1556 | E7: 1274 | F7: 945 | G7: -14 | H7: 1288 | I7: 1276 | J7: 943 | K7: 1302 | L7: 1057
