Workbook

Sheet Cover
A1: Moderna, Inc. (MRNA) - Intrinsic Value Model
A2: Valuation date 2026-09-30 | Prices as of 2026-09-25/28 | USD billions unless stated | Analysis, not investment advice
A4: Market price ($) | C4: =Drivers!$C$5 -> 199
A5: Probability-weighted DCF ($/share) | C5: =Summary!C10 -> 28.765561
A6: Blended intrinsic value ($/share) | C6: =Summary!F19 -> 33.087699
A7: Base scenario ($/share) | C7: =Summary!C7 -> 26.47574
A8: Bull scenario ($/share) | C8: =Summary!C8 -> 72.179586
A9: Blue-sky ceiling ($/share) | C9: =Summary!C9 -> 272.72192
A10: Monte Carlo P10 / P50 / P90 | C10: =TEXT(6.90160125596957,"$0")&" / "&TEXT(28.557500697222,"$0")&" / "&TEXT(63.6353294338,"$0") -> $7 / $29 / $64
A11: WACC (build-up) | C11: =Drivers!$C$30 -> 0.1043
A14: Legend: blue = hard-coded input (edit on Drivers); black = formula; green = link to another sheet; yellow fill = key assumption.
A15: How to use: change any blue cell on Drivers (e.g. INT melanoma peak, PoS, price factor, WACC) and every scenario, the SOTP and the Summary recalculate.
A16: M_* sheets are identical formula grids; only cell C2 (scenario index) differs. Monte Carlo, tornado, comps and guidance tabs are pasted engine outputs.
A17: Engine: scripts/valuation_engine.py reads data/assumptions.json; scripts/audit_model.py recalculates this workbook in LibreOffice and checks it matches the engine.

Sheet Summary
A1: Moderna (MRNA) - Probability-weighted intrinsic value
A2: Analysis, not investment advice. Values in $/share unless stated. Valuation date 2026-09-30.
A4: Scenario | B4: Probability | C4: Value/share | D4: EV ($B) | E4: Equity ($B) | F4: TV share of EV | G4: vs price
A5: Failure | B5: =Drivers!D56 -> 0.1 | C5: =M_Failure!$C$109 -> 6.9016013 | D5: =M_Failure!$C$103 -> -7.8042261 | E5: =M_Failure!$C$107 -> -5.1164168 | F5: =M_Failure!$C$104 -> 0 | G5: =C5/Drivers!$C$5-1 -> -0.96531859
A6: Bear | B6: =Drivers!E56 -> 0.25 | C6: =M_Bear!$C$109 -> 6.9016013 | D6: =M_Bear!$C$103 -> -4.0242469 | E6: =M_Bear!$C$107 -> -1.1364375 | F6: =M_Bear!$C$104 -> 0 | G6: =C6/Drivers!$C$5-1 -> -0.96531859
A7: Base | B7: =Drivers!F56 -> 0.45 | C7: =M_Base!$C$109 -> 26.47574 | D7: =M_Base!$C$103 -> 7.7281382 | E7: =M_Base!$C$107 -> 10.915948 | F7: =M_Base!$C$104 -> 0.18776475 | G7: =C7/Drivers!$C$5-1 -> -0.86695608
A8: Bull | B8: =Drivers!G56 -> 0.2 | C8: =M_Bull!$C$109 -> 72.179586 | D8: =M_Bull!$C$103 -> 27.305042 | E8: =M_Bull!$C$107 -> 30.692851 | F8: =M_Bull!$C$104 -> 0.19205377 | G8: =C8/Drivers!$C$5-1 -> -0.63728851
A9: Blue-sky (ceiling, unweighted) | B9: =Drivers!H56 -> 0 | C9: =M_BlueSky!$C$109 -> 272.72192 | D9: =M_BlueSky!$C$103 -> 115.82159 | E9: =M_BlueSky!$C$107 -> 119.19218 | F9: =M_BlueSky!$C$104 -> 0.41451048 | G9: =C9/Drivers!$C$5-1 -> 0.37046193
A10: Probability-weighted DCF value | C10: =SUMPRODUCT(B5:B8,C5:C8) -> 28.765561
A12: Method | B12: Low | C12: Mid | D12: High | E12: Weight | F12: Weighted | G12: Rationale
A13: Scenario rNPV/FCFF DCF (prob.-weighted) | B13: =C6 -> 6.9016013 | C13: =C10 -> 28.765561 | D13: =C8 -> 72.179586 | E13: 0.45 | F13: =C13*E13 -> 12.944502 | G13: Primary; asset-level risk explicit
A14: Monte Carlo (engine output, 20k draws) | B14: 6.9016013 | C14: 32.978244 | D14: 63.635329 | E14: 0.25 | F14: =C14*E14 -> 8.244561 | G14: P10 / mean / P90 from valuation_engine.py
A15: Forward peer multiple (EV/Sales 2030E) | B15: =$J$50 -> 22.034724 | C15: =$J$52 -> 30.409481 | D15: =$J$54 -> 38.784238 | E15: 0.15 | F15: =C15*E15 -> 4.5614221 | G15: Regression on 13 commercial peers
A16: Transaction reference (EV/risk-adj. peak) | B16: =$J$58 -> 51.963482 | C16: =($J$58+$J$59)/2 -> 68.807964 | D16: =$J$59 -> 85.652447 | E16: 0.1 | F16: =C16*E16 -> 6.8807964 | G16: Control value; includes acquirer synergies
A17: Earnings power value (no growth) | B17: =$J$64 -> 11.355086 | C17: =$J$64 -> 11.355086 | D17: =$J$64 -> 11.355086 | E17: 0.025 | F17: =C17*E17 -> 0.28387715 | G17: What exists today
A18: Asset / liquidation floor | B18: =Drivers!$C$141 -> 6.9016013 | C18: =Drivers!$C$141 -> 6.9016013 | D18: =Drivers!$C$141 -> 6.9016013 | E18: 0.025 | F18: =C18*E18 -> 0.17254003 | G18: Downside floor
A19: Blended intrinsic value (credibility-weighted) | E19: =SUM(E13:E18) -> 1 | F19: =SUM(F13:F18) -> 33.087699
A20: Market price | F20: =Drivers!$C$5 -> 199
A21: Blended value vs price | F21: =F19/Drivers!$C$5-1 -> -0.83373016
A23: Monte Carlo distribution (engine output)
A24: Statistic | B24: $/share
A25: P5 | B25: 6.9016013
A26: P10 | B26: 6.9016013
A27: P25 | B27: 14.115153
A28: P50 | B28: 28.557501
A29: P75 | B29: 45.325864
A30: P90 | B30: 63.635329
A31: P95 | B31: 77.309893
A32: P99 | B32: 108.53126
A33: mean | B33: 32.978244
A34: P(value > market price) | B34: 0.00025
A36: Reverse DCF (engine output)
A37: Implied INT risk-adj. peak sales ($B), all else base | B37: 81.406429
A38: Required unadjusted INT peak if every indication succeeds, base terms ($B) | B38: 93.466816
A39: ...and with bull price/margin/respiratory ($B) | B39: 51.209472 | I39: Auxiliary calculations
A40: Base-case unadjusted INT peak (10 indications, $B) | B40: 22 | I40: Regression const (ln EV/S) | J40: 1.3889575
A41: Implied WACC on base cash flows | B41: 0.019777133 | I41: Regression coef: 3y revenue CAGR | J41: 1.174444
A42: Implied probability of Blue-sky vs Bull | B42: 0.63238723 | I42: Regression coef: operating margin | J42: 0.23300818
I43: Base attributable revenue 2030 | J43: =M_Base!F81 -> 4.2898
I44: 3y CAGR 2027-30 | J44: =(M_Base!F81/M_Base!C81)^(1/3)-1 -> 0.19051078
...

Sheet Drivers
A1: DRIVERS - every model input (blue = hard-coded input; edit here). Units: USD billions unless stated.
A4: 1. Market & capital structure (valuation date 2026-09-30)
B5: Market price ($/share) | C5: 199 | D5: Nasdaq close 2026-09-25 $198.88; intraday 2026-09-28 ~$198-199 (data/mrna_price_daily.csv, data/peer_quotes_2026-09-28.json)
B6: Cash & investments, est. 9/30/26 | C6: 8.04 | D6: Jun-30-26 $6.910B (10-Q) - $0.950B Arbutus payment (Jul-26) + $2.628B convert net of capped call (8-K 2026-09-01: 2.9573-0.3288) - ~$0.55B est. Q3 operating burn (implied by YE-26 guide $4.7-5.2B ex-convert, 8-K 2026-07-31). Q3-26 10-Q not yet filed: ESTIMATE
B7: Ares term loan | C7: 0.6 | D7: Ares senior secured, SOFR+5.50% (~9.2%), matures 2030-11-24 (10-Q Q2-26 note 11)
B8: Convertible notes 2032 (face) | C8: 3 | D8: 0.00% notes due 2032-03-01, capped call to $392.62 (8-K 2026-09-01). Treated as debt at face; net share dilution only above the cap.
B9: Conversion price ($) | C9: 210.58
B10: Capped-call cap ($) | C10: 392.62
B11: Convert shares (m) | C11: 14.2461
B12: Finance leases | C12: 0.037
B13: Arbutus contingent payment | C13: 1.3 | D13: Settlement 8-K 2026-03-05: $1.3B due if Federal Circuit affirms rejection of s.1498 defence; pro-rated if partial. Probabilities JUDGMENT (Fed. Cir. affirmance base rate ~70%).
B14: P(pay in full) | C14: 0.6
B15: P(partial) | C15: 0.1
B16: Partial fraction | C16: 0.5
B17: Years to payment | C17: 1
B18: Pfizer/BioNTech litigation option | C18: 0.05 | D18: EP'949 revoked by EPO Board of Appeal Sep-2026 (JUVE Patent), nullifying UK/Dusseldorf wins; US patents invalidated at PTAB (on appeal). Residual option value JUDGMENT.
B19: Basic shares (m) | C19: 399.3 | D19: Nasdaq market cap $79.57B / $199.285 = 399.3M (2026-09-28); 10-Q Q2-26 weighted basic 398M
B20: Options (m) | C20: 29 | D20: 10-K 2025: 27.18M options @ $38.63 WAEP, 11.20M RSU/PSU; 10-Q Q2-26: 42M anti-dilutive equivalents. 2026 split ESTIMATED.
B21: Options WAEP ($) | C21: 40
B22: RSU/PSU (m) | C22: 13
A24: 2. Discount rate & tax
B25: Risk-free (10y UST) | C25: 0.0517 | D25: 10-yr UST 2026-09-25 (home.treasury.gov, data/ust_yields_2026.csv)
B26: Equity risk premium | C26: 0.045 | D26: JUDGMENT; implied US ERP range 4-5.5%
B27: Beta | C27: 1.2 | D27: Weekly vs SPY, 3y ex Aug-19-2026 jump = 1.32, 5y = 1.17; Blume-adjusted 1.11-1.22 (data/beta_estimates.json)
B28: Pre-tax cost of debt | C28: 0.075
B29: Debt weight | C29: 0.045
B30: WACC (build-up; used by Base) | C30: =ROUND((1-Drivers!$C$29)*(Drivers!$C$25+Drivers!$C$27*Drivers!$C$26)+Drivers!$C$29*Drivers!$C$28,4) -> 0.1043 | D30: (1-4.5pct) x CoE [5.17 + 1.20 x 4.5 = 10.57pct] + 4.5pct x 7.5pct pre-tax (NOLs remove the debt tax shield) = 10.43pct
B31: Cash tax rate | C31: 0.19 | D31: 21% federal + state, less FDII/credits; JUDGMENT
B32: NOL / deduction pool at 9/30/26 | C32: 12.5 | D32: Federal NOL $4.1B (10-K 2025 note 14, non-expiring) + 2026 tax loss ~$2.9B + ~$5.5B of unamortized capitalised R&E deductible after the 2025 tax act (DTA $1.693B / ~23%, domestic portion) -> ~$12.5B. ESTIMATE.
B33: NOL usage limit (% of taxable income) | C33: 0.8
B34: Q4-2026 stub FCF | C34: -0.46 | D34: Q4-26 operating cash burn implied by YE-26 cash guide midpoint $4.95B (8-K 2026-07-31) after est. Q3 burn
B35: 2026 revenue base (for working capital) | C35: 2.04 | D35: Guidance-tracker base case (data/guidance_forward_adjusted.csv)
A37: 3. Scenario levers (columns D..H = Failure, Bear, Base, Bull, Blue-sky; Blue-sky is a ceiling test, not weighted)
B38: Lever | D38: Failure | E38: Bear | F38: Base | G38: Bull | H38: Blue-sky | I38: Note
B39: COVID revenue multiplier | D39: 0.75 | E39: 0.85 | F39: 1 | G39: 1.1 | H39: 1.1
B40: Flu (mFLUSIVA) peak multiplier | D40: 0.5 | E40: 0.6 | F40: 1 | G40: 1.6 | H40: 1.6
B41: Flu+COVID combo peak multiplier | D41: 0.5 | E41: 0.6 | F41: 1 | G41: 1.6 | H41: 1.6
B42: Norovirus PoS | D42: 0.15 | E42: 0.2 | F42: 0.3 | G42: 0.45 | H42: 1
B43: Respiratory gross-margin shift | D43: -0.04 | E43: -0.02 | F43: 0 | G43: 0.02 | H43: 0.03
B44: INT melanoma PoS | D44: 0 | E44: 0.85 | F44: 0.88 | G44: 0.93 | H44: 1
...

Sheet SOTP
A1: Sum-of-the-parts - Base scenario (pre-tax PV incl. pro-rata terminal value; tax shown separately)
A3: Component | B3: PV ($B) | C3: $ / share (on basic) | D3: Note
A4: Respiratory franchise | B4: =1*(SUMPRODUCT(M_Base!C52:U52,M_Base!C92:U92)+M_Base!$C$100*M_Base!U52/M_Base!U90) -> 13.773608 | C4: =B4*1000/Drivers!$C$19 -> 34.494385 | D4: COVID, flu, combo, RSV, norovirus
A5: Intismeran (50% share, net of dev.) | B5: =1*(SUMPRODUCT(M_Base!C68:U68,M_Base!C92:U92)+M_Base!$C$100*M_Base!U68/M_Base!U90) -> 6.6417922 | C5: =B5*1000/Drivers!$C$19 -> 16.633589 | D5: 10 indications, PoS-weighted
A6: mRNA-4359 | B6: =1*(SUMPRODUCT(M_Base!C72:U72,M_Base!C92:U92)+M_Base!$C$100*M_Base!U72/M_Base!U90) -> -0.19104088 | C6: =B6*1000/Drivers!$C$19 -> -0.47843947 | D6: wholly owned
A7: Rare disease & royalties | B7: =1*(SUMPRODUCT(M_Base!C76:U76,M_Base!C92:U92)+M_Base!$C$100*M_Base!U76/M_Base!U90) -> 0.44361461 | C7: =B7*1000/Drivers!$C$19 -> 1.1109807 | D7: PA (Recordati), MMA, CF
A8: Corporate G&A | B8: =-1*(SUMPRODUCT(M_Base!C78:U78,M_Base!C92:U92)+M_Base!$C$100*M_Base!U78/M_Base!U90) -> -4.8294873 | C8: =B8*1000/Drivers!$C$19 -> -12.094884
A9: Unallocated R&D (platform/shared/SBC) | B9: =-1*(SUMPRODUCT(M_Base!C80:U80,M_Base!C92:U92)+M_Base!$C$100*M_Base!U80/M_Base!U90) -> -11.864245 | C9: =B9*1000/Drivers!$C$19 -> -29.71261 | D9: credited below via future-pipeline line
A10: Cash taxes (after NOLs) | B10: =-1*(SUMPRODUCT(M_Base!C88:U88,M_Base!C92:U92)+M_Base!$C$100*M_Base!U88/M_Base!U90) -> -0.29227645 | C10: =B10*1000/Drivers!$C$19 -> -0.73197208
A11: Net capex & working capital | B11: =-(SUMPRODUCT(M_Base!C82:U82,M_Base!C92:U92)-SUMPRODUCT(M_Base!C83:U83,M_Base!C92:U92)+SUMPRODUCT(M_Base!C84:U84,M_Base!C92:U92))-M_Base!$C$100*(M_Base!U82-M_Base!U83+M_Base!U84)/M_Base!U90 -> -0.73268555 | C11: =B11*1000/Drivers!$C$19 -> -1.834925
A12: Q4-2026 stub cash burn | B12: =M_Base!$C$97 -> -0.45433056 | C12: =B12*1000/Drivers!$C$19 -> -1.1378176
A13: Unidentified future pipeline (credit) | B13: =M_Base!$C$102 -> 5.2331894 | C13: =B13*1000/Drivers!$C$19 -> 13.105909
A14: Enterprise value (sum) | B14: =SUM(B4:B13) -> 7.7281382 | C14: =B14*1000/Drivers!$C$19 -> 19.354215 | D14: check vs M_Base EV: | E14: =B14-M_Base!$C$103 -> 0
A15: + Cash & investments (est.) | B15: =Drivers!$C$6 -> 8.04 | C15: =B15*1000/Drivers!$C$19 -> 20.135237
A16: - Term loan | B16: =-Drivers!$C$7 -> -0.6 | C16: =B16*1000/Drivers!$C$19 -> -1.5026296
A17: - Convertible notes (face) | B17: =-Drivers!$C$8 -> -3 | C17: =B17*1000/Drivers!$C$19 -> -7.513148
A18: - Finance leases | B18: =-Drivers!$C$12 -> -0.037 | C18: =B18*1000/Drivers!$C$19 -> -0.092662159
A19: - Arbutus contingent (expected PV) | B19: =-M_Base!$C$105 -> -0.76519062 | C19: =B19*1000/Drivers!$C$19 -> -1.9163301
A20: - Other patent litigation | B20: =-M_Base!$C$21 -> -0.5 | C20: =B20*1000/Drivers!$C$19 -> -1.2521913
A21: + Pfizer/BioNTech litigation option | B21: =Drivers!$C$18 -> 0.05 | C21: =B21*1000/Drivers!$C$19 -> 0.12521913
A22: Equity value (sum) | B22: =SUM(B14:B21) -> 10.915948 | C22: =B22*1000/Drivers!$C$19 -> 27.33771
A23: Value per share (Base) | B23: =M_Base!$C$109 -> 26.47574

Sheet M_Failure
A1: M_Failure - scenario model (ESMO data weak (HR ~0.85) / FDA (CBER) requires OS -> melanoma not approved; readthrough cuts other INT PoS by 60%; respiratory bear.)
A2: Scenario index (1=Failure..5=Blue-sky) | C2: 1
A4: Scenario levers (green = pulled from Drivers)
A5: COVID revenue multiplier | C5: =INDEX(Drivers!$D$39:$H$39,$C$2) -> 0.75
A6: Flu (mFLUSIVA) peak multiplier | C6: =INDEX(Drivers!$D$40:$H$40,$C$2) -> 0.5
A7: Flu+COVID combo peak multiplier | C7: =INDEX(Drivers!$D$41:$H$41,$C$2) -> 0.5
A8: Norovirus PoS | C8: =INDEX(Drivers!$D$42:$H$42,$C$2) -> 0.15
A9: Respiratory gross-margin shift | C9: =INDEX(Drivers!$D$43:$H$43,$C$2) -> -0.04
A10: INT melanoma PoS | C10: =INDEX(Drivers!$D$44:$H$44,$C$2) -> 0
A11: INT melanoma peak global sales ($B, before price factor) | C11: =INDEX(Drivers!$D$45:$H$45,$C$2) -> 2.8
A12: INT melanoma launch year | C12: =INDEX(Drivers!$D$46:$H$46,$C$2) -> 2027
A13: INT other-indication PoS multiplier (>=10 => all 100%) | C13: =INDEX(Drivers!$D$47:$H$47,$C$2) -> 0.4
A14: INT other-indication peak multiplier | C14: =INDEX(Drivers!$D$48:$H$48,$C$2) -> 0.8
A15: INT price factor (1.0 = US net ~$300k) | C15: =INDEX(Drivers!$D$49:$H$49,$C$2) -> 0.8
A16: INT mature profit-pool margin | C16: =INDEX(Drivers!$D$50:$H$50,$C$2) -> 0.55
A17: Unallocated R&D multiplier | C17: =INDEX(Drivers!$D$51:$H$51,$C$2) -> 0.6
A18: Future-pipeline credit factor | C18: =INDEX(Drivers!$D$52:$H$52,$C$2) -> 0.25
A19: WACC | C19: =INDEX(Drivers!$D$53:$H$53,$C$2) -> 0.1043
A20: Terminal growth | C20: =INDEX(Drivers!$D$54:$H$54,$C$2) -> -0.01
A21: Other patent litigation (expected cost) | C21: =INDEX(Drivers!$D$55:$H$55,$C$2) -> 1
A22: INT indications: scenario-adjusted launch / peak / PoS
A23: Indication | C23: Launch | D23: Peak | E23: PoS
A24: =Drivers!$B$95 -> Adjuvant melanoma IIB-IV (INTerpath-001) | C24: =$C$12 -> 2027 | D24: =$C$11 -> 2.8 | E24: =$C$10 -> 0
A25: =Drivers!$B$96 -> Adjuvant NSCLC II-IIIB (INTerpath-002) | C25: =Drivers!$D$96 -> 2031 | D25: =Drivers!$E$96*$C$14 -> 3.2 | E25: =MIN(Drivers!$F$96*$C$13,IF($C$13>=10,1,0.95)) -> 0.18
A26: =Drivers!$B$97 -> Post-neoadjuvant non-pCR NSCLC (INTerpath-009) | C26: =Drivers!$D$97 -> 2034 | D26: =Drivers!$E$97*$C$14 -> 1.2 | E26: =MIN(Drivers!$F$97*$C$13,IF($C$13>=10,1,0.95)) -> 0.16
A27: =Drivers!$B$98 -> Resected stage I NSCLC (INTerpath-014) | C27: =Drivers!$D$98 -> 2035 | D27: =Drivers!$E$98*$C$14 -> 2 | E27: =MIN(Drivers!$F$98*$C$13,IF($C$13>=10,1,0.95)) -> 0.14
A28: =Drivers!$B$99 -> Adjuvant RCC (INTerpath-004) | C28: =Drivers!$D$99 -> 2031 | D28: =Drivers!$E$99*$C$14 -> 0.96 | E28: =MIN(Drivers!$F$99*$C$13,IF($C$13>=10,1,0.95)) -> 0.1
A29: =Drivers!$B$100 -> MIBC adjuvant (INTerpath-005) | C29: =Drivers!$D$100 -> 2033 | D29: =Drivers!$E$100*$C$14 -> 0.8 | E29: =MIN(Drivers!$F$100*$C$13,IF($C$13>=10,1,0.95)) -> 0.08
A30: =Drivers!$B$101 -> NMIBC + BCG (INTerpath-011) | C30: =Drivers!$D$101 -> 2034 | D30: =Drivers!$E$101*$C$14 -> 0.8 | E30: =MIN(Drivers!$F$101*$C$13,IF($C$13>=10,1,0.95)) -> 0.06
A31: =Drivers!$B$102 -> 1L advanced melanoma (INTerpath-012) | C31: =Drivers!$D$102 -> 2031 | D31: =Drivers!$E$102*$C$14 -> 0.64 | E31: =MIN(Drivers!$F$102*$C$13,IF($C$13>=10,1,0.95)) -> 0.08
A32: =Drivers!$B$103 -> 1L metastatic squamous NSCLC (INTerpath-013) | C32: =Drivers!$D$103 -> 2032 | D32: =Drivers!$E$103*$C$14 -> 0.96 | E32: =MIN(Drivers!$F$103*$C$13,IF($C$13>=10,1,0.95)) -> 0.06
A33: =Drivers!$B$104 -> Other solid tumours - future INT indications (pre-Ph2) | C33: =Drivers!$D$104 -> 2035 | D33: =Drivers!$E$104*$C$14 -> 4.8 | E33: =MIN(Drivers!$F$104*$C$13,IF($C$13>=10,1,0.95)) -> 0.04
A35: Year | B35: unit | C35: 2027 | D35: 2028 | E35: 2029 | F35: 2030 | G35: 2031 | H35: 2032 | I35: 2033 | J35: 2034 | K35: 2035 | L35: 2036 | M35: 2037 | N35: 2038 | O35: 2039 | P35: 2040 | Q35: 2041 | R35: 2042 | S35: 2043 | T35: 2044 | U35: 2045
A36: Year index i | C36: 0 | D36: 1 | E36: 2 | F36: 3 | G36: 4 | H36: 5 | I36: 6 | J36: 7 | K36: 8 | L36: 9 | M36: 10 | N36: 11 | O36: 12 | P36: 13 | Q36: 14 | R36: 15 | S36: 16 | T36: 17 | U36: 18
A37: RESPIRATORY FRANCHISE
A38: COVID (Spikevax, mNEXSPIKE, partnerships) | B38: $B | C38: =Drivers!$D$60*$C$5 -> 1.3875 | D38: =Drivers!$E$60*$C$5 -> 1.275 | E38: =Drivers!$F$60*$C$5 -> 1.1625 | F38: =Drivers!$G$60*$C$5 -> 1.0875 | G38: =Drivers!$H$60*$C$5 -> 1.035 | H38: =Drivers!$I$60*$C$5 -> 0.975 | I38: =H38*(1+Drivers!$C$61) -> 0.9555 | J38: =I38*(1+Drivers!$C$61) -> 0.93639 | K38: =J38*(1+Drivers!$C$61) -> 0.9176622 | L38: =K38*(1+Drivers!$C$61) -> 0.89930896 | M38: =L38*(1+Drivers!$C$61) -> 0.88132278 | N38: =M38*(1+Drivers!$C$61) -> 0.86369632 | O38: =N38*(1+Drivers!$C$61) -> 0.84642239 | P38: =O38*(1+Drivers!$C$61) -> 0.82949395 | ... U38: =T38*(1+Drivers!$C$61) -> 0.74979683
A39: Flu (mFLUSIVA) | B39: $B | C39: =Drivers!$C$62*IF((C$35-Drivers!$C$63)<0,0,MIN(((C$35-Drivers!$C$63)+1)/Drivers!$C$64,1))*$C$6 -> 0.08 | D39: =Drivers!$C$62*IF((D$35-Drivers!$C$63)<0,0,MIN(((D$35-Drivers!$C$63)+1)/Drivers!$C$64,1))*$C$6 -> 0.16 | E39: =Drivers!$C$62*IF((E$35-Drivers!$C$63)<0,0,MIN(((E$35-Drivers!$C$63)+1)/Drivers!$C$64,1))*$C$6 -> 0.24 | F39: =Drivers!$C$62*IF((F$35-Drivers!$C$63)<0,0,MIN(((F$35-Drivers!$C$63)+1)/Drivers!$C$64,1))*$C$6 -> 0.32 | G39: =Drivers!$C$62*IF((G$35-Drivers!$C$63)<0,0,MIN(((G$35-Drivers!$C$63)+1)/Drivers!$C$64,1))*$C$6 -> 0.4 | H39: =Drivers!$C$62*IF((H$35-Drivers!$C$63)<0,0,MIN(((H$35-Drivers!$C$63)+1)/Drivers!$C$64,1))*$C$6 -> 0.4 | I39: =Drivers!$C$62*IF((I$35-Drivers!$C$63)<0,0,MIN(((I$35-Drivers!$C$63)+1)/Drivers!$C$64,1))*$C$6 -> 0.4 | J39: =Drivers!$C$62*IF((J$35-Drivers!$C$63)<0,0,MIN(((J$35-Drivers!$C$63)+1)/Drivers!$C$64,1))*$C$6 -> 0.4 | ... U39: =Drivers!$C$62*IF((U$35-Drivers!$C$63)<0,0,MIN(((U$35-Drivers!$C$63)+1)/Drivers!$C$64,1))*$C$6 -> 0.4
A40: Flu+COVID combo (mCOMBRIAX) | B40: $B | C40: =Drivers!$C$65*IF((C$35-Drivers!$C$66)<0,0,MIN(((C$35-Drivers!$C$66)+1)/Drivers!$C$67,1))*$C$7*((1-Drivers!$C$69)+Drivers!$C$69*Drivers!$C$68) -> 0.1169 | D40: =Drivers!$C$65*IF((D$35-Drivers!$C$66)<0,0,MIN(((D$35-Drivers!$C$66)+1)/Drivers!$C$67,1))*$C$7*((1-Drivers!$C$69)+Drivers!$C$69*Drivers!$C$68) -> 0.2338 | E40: =Drivers!$C$65*IF((E$35-Drivers!$C$66)<0,0,MIN(((E$35-Drivers!$C$66)+1)/Drivers!$C$67,1))*$C$7*((1-Drivers!$C$69)+Drivers!$C$69*Drivers!$C$68) -> 0.3507 | F40: =Drivers!$C$65*IF((F$35-Drivers!$C$66)<0,0,MIN(((F$35-Drivers!$C$66)+1)/Drivers!$C$67,1))*$C$7*((1-Drivers!$C$69)+Drivers!$C$69*Drivers!$C$68) -> 0.4676 | G40: =Drivers!$C$65*IF((G$35-Drivers!$C$66)<0,0,MIN(((G$35-Drivers!$C$66)+1)/Drivers!$C$67,1))*$C$7*((1-Drivers!$C$69)+Drivers!$C$69*Drivers!$C$68) -> 0.5845 | H40: =Drivers!$C$65*IF((H$35-Drivers!$C$66)<0,0,MIN(((H$35-Drivers!$C$66)+1)/Drivers!$C$67,1))*$C$7*((1-Drivers!$C$69)+Drivers!$C$69*Drivers!$C$68) -> 0.5845 | I40: =Drivers!$C$65*IF((I$35-Drivers!$C$66)<0,0,MIN(((I$35-Drivers!$C$66)+1)/Drivers!$C$67,1))*$C$7*((1-Drivers!$C$69)+Drivers!$C$69*Drivers!$C$68) -> 0.5845 | J40: =Drivers!$C$65*IF((J$35-Drivers!$C$66)<0,0,MIN(((J$35-Drivers!$C$66)+1)/Drivers!$C$67,1))*$C$7*((1-Drivers!$C$69)+Drivers!$C$69*Drivers!$C$68) -> 0.5845 | ... U40: =Drivers!$C$65*IF((U$35-Drivers!$C$66)<0,0,MIN(((U$35-Drivers!$C$66)+1)/Drivers!$C$67,1))*$C$7*((1-Drivers!$C$69)+Drivers!$C$69*Drivers!$C$68) -> 0.5845
A41: RSV (mRESVIA) | B41: $B | C41: =Drivers!$C$70*MIN((C$35-2026)/3,1) -> 0.05 | D41: =Drivers!$C$70*MIN((D$35-2026)/3,1) -> 0.1 | E41: =Drivers!$C$70*MIN((E$35-2026)/3,1) -> 0.15 | F41: =Drivers!$C$70*MIN((F$35-2026)/3,1) -> 0.15 | G41: =Drivers!$C$70*MIN((G$35-2026)/3,1) -> 0.15 | H41: =Drivers!$C$70*MIN((H$35-2026)/3,1) -> 0.15 | I41: =Drivers!$C$70*MIN((I$35-2026)/3,1) -> 0.15 | J41: =Drivers!$C$70*MIN((J$35-2026)/3,1) -> 0.15 | ... U41: =Drivers!$C$70*MIN((U$35-2026)/3,1) -> 0.15
A42: Norovirus (risk-adjusted) | B42: $B | C42: =$C$8*Drivers!$C$71*IF((C$35-Drivers!$C$72)<0,0,MIN(((C$35-Drivers!$C$72)+1)/Drivers!$C$73,1)) -> 0 | D42: =$C$8*Drivers!$C$71*IF((D$35-Drivers!$C$72)<0,0,MIN(((D$35-Drivers!$C$72)+1)/Drivers!$C$73,1)) -> 0 | E42: =$C$8*Drivers!$C$71*IF((E$35-Drivers!$C$72)<0,0,MIN(((E$35-Drivers!$C$72)+1)/Drivers!$C$73,1)) -> 0.036 | F42: =$C$8*Drivers!$C$71*IF((F$35-Drivers!$C$72)<0,0,MIN(((F$35-Drivers!$C$72)+1)/Drivers!$C$73,1)) -> 0.072 | G42: =$C$8*Drivers!$C$71*IF((G$35-Drivers!$C$72)<0,0,MIN(((G$35-Drivers!$C$72)+1)/Drivers!$C$73,1)) -> 0.108 | H42: =$C$8*Drivers!$C$71*IF((H$35-Drivers!$C$72)<0,0,MIN(((H$35-Drivers!$C$72)+1)/Drivers!$C$73,1)) -> 0.144 | I42: =$C$8*Drivers!$C$71*IF((I$35-Drivers!$C$72)<0,0,MIN(((I$35-Drivers!$C$72)+1)/Drivers!$C$73,1)) -> 0.18 | J42: =$C$8*Drivers!$C$71*IF((J$35-Drivers!$C$72)<0,0,MIN(((J$35-Drivers!$C$72)+1)/Drivers!$C$73,1)) -> 0.18 | ... U42: =$C$8*Drivers!$C$71*IF((U$35-Drivers!$C$72)<0,0,MIN(((U$35-Drivers!$C$72)+1)/Drivers!$C$73,1)) -> 0.18
...

Sheet M_Bear
A1: M_Bear - scenario model (Melanoma approved 2028 with modest HR (~0.75), price ~$200k US; NSCLC PoS cut; COVID erodes faster; flu/combo half of base.)
A2: Scenario index (1=Failure..5=Blue-sky) | C2: 2
A4: Scenario levers (green = pulled from Drivers)
A5: COVID revenue multiplier | C5: =INDEX(Drivers!$D$39:$H$39,$C$2) -> 0.85
A6: Flu (mFLUSIVA) peak multiplier | C6: =INDEX(Drivers!$D$40:$H$40,$C$2) -> 0.6
A7: Flu+COVID combo peak multiplier | C7: =INDEX(Drivers!$D$41:$H$41,$C$2) -> 0.6
A8: Norovirus PoS | C8: =INDEX(Drivers!$D$42:$H$42,$C$2) -> 0.2
A9: Respiratory gross-margin shift | C9: =INDEX(Drivers!$D$43:$H$43,$C$2) -> -0.02
A10: INT melanoma PoS | C10: =INDEX(Drivers!$D$44:$H$44,$C$2) -> 0.85
A11: INT melanoma peak global sales ($B, before price factor) | C11: =INDEX(Drivers!$D$45:$H$45,$C$2) -> 1.5
A12: INT melanoma launch year | C12: =INDEX(Drivers!$D$46:$H$46,$C$2) -> 2028
A13: INT other-indication PoS multiplier (>=10 => all 100%) | C13: =INDEX(Drivers!$D$47:$H$47,$C$2) -> 0.7
A14: INT other-indication peak multiplier | C14: =INDEX(Drivers!$D$48:$H$48,$C$2) -> 0.8
A15: INT price factor (1.0 = US net ~$300k) | C15: =INDEX(Drivers!$D$49:$H$49,$C$2) -> 0.75
A16: INT mature profit-pool margin | C16: =INDEX(Drivers!$D$50:$H$50,$C$2) -> 0.55
A17: Unallocated R&D multiplier | C17: =INDEX(Drivers!$D$51:$H$51,$C$2) -> 0.85
A18: Future-pipeline credit factor | C18: =INDEX(Drivers!$D$52:$H$52,$C$2) -> 0.5
A19: WACC | C19: =INDEX(Drivers!$D$53:$H$53,$C$2) -> 0.1043
A20: Terminal growth | C20: =INDEX(Drivers!$D$54:$H$54,$C$2) -> -0.01
A21: Other patent litigation (expected cost) | C21: =INDEX(Drivers!$D$55:$H$55,$C$2) -> 0.8
A22: INT indications: scenario-adjusted launch / peak / PoS
A23: Indication | C23: Launch | D23: Peak | E23: PoS
A24: =Drivers!$B$95 -> Adjuvant melanoma IIB-IV (INTerpath-001) | C24: =$C$12 -> 2028 | D24: =$C$11 -> 1.5 | E24: =$C$10 -> 0.85
A25: =Drivers!$B$96 -> Adjuvant NSCLC II-IIIB (INTerpath-002) | C25: =Drivers!$D$96 -> 2031 | D25: =Drivers!$E$96*$C$14 -> 3.2 | E25: =MIN(Drivers!$F$96*$C$13,IF($C$13>=10,1,0.95)) -> 0.315
A26: =Drivers!$B$97 -> Post-neoadjuvant non-pCR NSCLC (INTerpath-009) | C26: =Drivers!$D$97 -> 2034 | D26: =Drivers!$E$97*$C$14 -> 1.2 | E26: =MIN(Drivers!$F$97*$C$13,IF($C$13>=10,1,0.95)) -> 0.28
A27: =Drivers!$B$98 -> Resected stage I NSCLC (INTerpath-014) | C27: =Drivers!$D$98 -> 2035 | D27: =Drivers!$E$98*$C$14 -> 2 | E27: =MIN(Drivers!$F$98*$C$13,IF($C$13>=10,1,0.95)) -> 0.245
A28: =Drivers!$B$99 -> Adjuvant RCC (INTerpath-004) | C28: =Drivers!$D$99 -> 2031 | D28: =Drivers!$E$99*$C$14 -> 0.96 | E28: =MIN(Drivers!$F$99*$C$13,IF($C$13>=10,1,0.95)) -> 0.175
A29: =Drivers!$B$100 -> MIBC adjuvant (INTerpath-005) | C29: =Drivers!$D$100 -> 2033 | D29: =Drivers!$E$100*$C$14 -> 0.8 | E29: =MIN(Drivers!$F$100*$C$13,IF($C$13>=10,1,0.95)) -> 0.14
A30: =Drivers!$B$101 -> NMIBC + BCG (INTerpath-011) | C30: =Drivers!$D$101 -> 2034 | D30: =Drivers!$E$101*$C$14 -> 0.8 | E30: =MIN(Drivers!$F$101*$C$13,IF($C$13>=10,1,0.95)) -> 0.105
A31: =Drivers!$B$102 -> 1L advanced melanoma (INTerpath-012) | C31: =Drivers!$D$102 -> 2031 | D31: =Drivers!$E$102*$C$14 -> 0.64 | E31: =MIN(Drivers!$F$102*$C$13,IF($C$13>=10,1,0.95)) -> 0.14
A32: =Drivers!$B$103 -> 1L metastatic squamous NSCLC (INTerpath-013) | C32: =Drivers!$D$103 -> 2032 | D32: =Drivers!$E$103*$C$14 -> 0.96 | E32: =MIN(Drivers!$F$103*$C$13,IF($C$13>=10,1,0.95)) -> 0.105
A33: =Drivers!$B$104 -> Other solid tumours - future INT indications (pre-Ph2) | C33: =Drivers!$D$104 -> 2035 | D33: =Drivers!$E$104*$C$14 -> 4.8 | E33: =MIN(Drivers!$F$104*$C$13,IF($C$13>=10,1,0.95)) -> 0.07
A35: Year | B35: unit | C35: 2027 | D35: 2028 | E35: 2029 | F35: 2030 | G35: 2031 | H35: 2032 | I35: 2033 | J35: 2034 | K35: 2035 | L35: 2036 | M35: 2037 | N35: 2038 | O35: 2039 | P35: 2040 | Q35: 2041 | R35: 2042 | S35: 2043 | T35: 2044 | U35: 2045
A36: Year index i | C36: 0 | D36: 1 | E36: 2 | F36: 3 | G36: 4 | H36: 5 | I36: 6 | J36: 7 | K36: 8 | L36: 9 | M36: 10 | N36: 11 | O36: 12 | P36: 13 | Q36: 14 | R36: 15 | S36: 16 | T36: 17 | U36: 18
A37: RESPIRATORY FRANCHISE
A38: COVID (Spikevax, mNEXSPIKE, partnerships) | B38: $B | C38: =Drivers!$D$60*$C$5 -> 1.5725 | D38: =Drivers!$E$60*$C$5 -> 1.445 | E38: =Drivers!$F$60*$C$5 -> 1.3175 | F38: =Drivers!$G$60*$C$5 -> 1.2325 | G38: =Drivers!$H$60*$C$5 -> 1.173 | H38: =Drivers!$I$60*$C$5 -> 1.105 | I38: =H38*(1+Drivers!$C$61) -> 1.0829 | J38: =I38*(1+Drivers!$C$61) -> 1.061242 | K38: =J38*(1+Drivers!$C$61) -> 1.0400172 | L38: =K38*(1+Drivers!$C$61) -> 1.0192168 | M38: =L38*(1+Drivers!$C$61) -> 0.99883248 | N38: =M38*(1+Drivers!$C$61) -> 0.97885583 | O38: =N38*(1+Drivers!$C$61) -> 0.95927871 | P38: =O38*(1+Drivers!$C$61) -> 0.94009314 | ... U38: =T38*(1+Drivers!$C$61) -> 0.84976974
A39: Flu (mFLUSIVA) | B39: $B | C39: =Drivers!$C$62*IF((C$35-Drivers!$C$63)<0,0,MIN(((C$35-Drivers!$C$63)+1)/Drivers!$C$64,1))*$C$6 -> 0.096 | D39: =Drivers!$C$62*IF((D$35-Drivers!$C$63)<0,0,MIN(((D$35-Drivers!$C$63)+1)/Drivers!$C$64,1))*$C$6 -> 0.192 | E39: =Drivers!$C$62*IF((E$35-Drivers!$C$63)<0,0,MIN(((E$35-Drivers!$C$63)+1)/Drivers!$C$64,1))*$C$6 -> 0.288 | F39: =Drivers!$C$62*IF((F$35-Drivers!$C$63)<0,0,MIN(((F$35-Drivers!$C$63)+1)/Drivers!$C$64,1))*$C$6 -> 0.384 | G39: =Drivers!$C$62*IF((G$35-Drivers!$C$63)<0,0,MIN(((G$35-Drivers!$C$63)+1)/Drivers!$C$64,1))*$C$6 -> 0.48 | H39: =Drivers!$C$62*IF((H$35-Drivers!$C$63)<0,0,MIN(((H$35-Drivers!$C$63)+1)/Drivers!$C$64,1))*$C$6 -> 0.48 | I39: =Drivers!$C$62*IF((I$35-Drivers!$C$63)<0,0,MIN(((I$35-Drivers!$C$63)+1)/Drivers!$C$64,1))*$C$6 -> 0.48 | J39: =Drivers!$C$62*IF((J$35-Drivers!$C$63)<0,0,MIN(((J$35-Drivers!$C$63)+1)/Drivers!$C$64,1))*$C$6 -> 0.48 | ... U39: =Drivers!$C$62*IF((U$35-Drivers!$C$63)<0,0,MIN(((U$35-Drivers!$C$63)+1)/Drivers!$C$64,1))*$C$6 -> 0.48
A40: Flu+COVID combo (mCOMBRIAX) | B40: $B | C40: =Drivers!$C$65*IF((C$35-Drivers!$C$66)<0,0,MIN(((C$35-Drivers!$C$66)+1)/Drivers!$C$67,1))*$C$7*((1-Drivers!$C$69)+Drivers!$C$69*Drivers!$C$68) -> 0.14028 | D40: =Drivers!$C$65*IF((D$35-Drivers!$C$66)<0,0,MIN(((D$35-Drivers!$C$66)+1)/Drivers!$C$67,1))*$C$7*((1-Drivers!$C$69)+Drivers!$C$69*Drivers!$C$68) -> 0.28056 | E40: =Drivers!$C$65*IF((E$35-Drivers!$C$66)<0,0,MIN(((E$35-Drivers!$C$66)+1)/Drivers!$C$67,1))*$C$7*((1-Drivers!$C$69)+Drivers!$C$69*Drivers!$C$68) -> 0.42084 | F40: =Drivers!$C$65*IF((F$35-Drivers!$C$66)<0,0,MIN(((F$35-Drivers!$C$66)+1)/Drivers!$C$67,1))*$C$7*((1-Drivers!$C$69)+Drivers!$C$69*Drivers!$C$68) -> 0.56112 | G40: =Drivers!$C$65*IF((G$35-Drivers!$C$66)<0,0,MIN(((G$35-Drivers!$C$66)+1)/Drivers!$C$67,1))*$C$7*((1-Drivers!$C$69)+Drivers!$C$69*Drivers!$C$68) -> 0.7014 | H40: =Drivers!$C$65*IF((H$35-Drivers!$C$66)<0,0,MIN(((H$35-Drivers!$C$66)+1)/Drivers!$C$67,1))*$C$7*((1-Drivers!$C$69)+Drivers!$C$69*Drivers!$C$68) -> 0.7014 | I40: =Drivers!$C$65*IF((I$35-Drivers!$C$66)<0,0,MIN(((I$35-Drivers!$C$66)+1)/Drivers!$C$67,1))*$C$7*((1-Drivers!$C$69)+Drivers!$C$69*Drivers!$C$68) -> 0.7014 | J40: =Drivers!$C$65*IF((J$35-Drivers!$C$66)<0,0,MIN(((J$35-Drivers!$C$66)+1)/Drivers!$C$67,1))*$C$7*((1-Drivers!$C$69)+Drivers!$C$69*Drivers!$C$68) -> 0.7014 | ... U40: =Drivers!$C$65*IF((U$35-Drivers!$C$66)<0,0,MIN(((U$35-Drivers!$C$66)+1)/Drivers!$C$67,1))*$C$7*((1-Drivers!$C$69)+Drivers!$C$69*Drivers!$C$68) -> 0.7014
A41: RSV (mRESVIA) | B41: $B | C41: =Drivers!$C$70*MIN((C$35-2026)/3,1) -> 0.05 | D41: =Drivers!$C$70*MIN((D$35-2026)/3,1) -> 0.1 | E41: =Drivers!$C$70*MIN((E$35-2026)/3,1) -> 0.15 | F41: =Drivers!$C$70*MIN((F$35-2026)/3,1) -> 0.15 | G41: =Drivers!$C$70*MIN((G$35-2026)/3,1) -> 0.15 | H41: =Drivers!$C$70*MIN((H$35-2026)/3,1) -> 0.15 | I41: =Drivers!$C$70*MIN((I$35-2026)/3,1) -> 0.15 | J41: =Drivers!$C$70*MIN((J$35-2026)/3,1) -> 0.15 | ... U41: =Drivers!$C$70*MIN((U$35-2026)/3,1) -> 0.15
A42: Norovirus (risk-adjusted) | B42: $B | C42: =$C$8*Drivers!$C$71*IF((C$35-Drivers!$C$72)<0,0,MIN(((C$35-Drivers!$C$72)+1)/Drivers!$C$73,1)) -> 0 | D42: =$C$8*Drivers!$C$71*IF((D$35-Drivers!$C$72)<0,0,MIN(((D$35-Drivers!$C$72)+1)/Drivers!$C$73,1)) -> 0 | E42: =$C$8*Drivers!$C$71*IF((E$35-Drivers!$C$72)<0,0,MIN(((E$35-Drivers!$C$72)+1)/Drivers!$C$73,1)) -> 0.048 | F42: =$C$8*Drivers!$C$71*IF((F$35-Drivers!$C$72)<0,0,MIN(((F$35-Drivers!$C$72)+1)/Drivers!$C$73,1)) -> 0.096 | G42: =$C$8*Drivers!$C$71*IF((G$35-Drivers!$C$72)<0,0,MIN(((G$35-Drivers!$C$72)+1)/Drivers!$C$73,1)) -> 0.144 | H42: =$C$8*Drivers!$C$71*IF((H$35-Drivers!$C$72)<0,0,MIN(((H$35-Drivers!$C$72)+1)/Drivers!$C$73,1)) -> 0.192 | I42: =$C$8*Drivers!$C$71*IF((I$35-Drivers!$C$72)<0,0,MIN(((I$35-Drivers!$C$72)+1)/Drivers!$C$73,1)) -> 0.24 | J42: =$C$8*Drivers!$C$71*IF((J$35-Drivers!$C$72)<0,0,MIN(((J$35-Drivers!$C$72)+1)/Drivers!$C$73,1)) -> 0.24 | ... U42: =$C$8*Drivers!$C$71*IF((U$35-Drivers!$C$72)<0,0,MIN(((U$35-Drivers!$C$72)+1)/Drivers!$C$73,1)) -> 0.24
...

Sheet M_Base
A1: M_Base - scenario model (Assumptions as listed: melanoma launch 2027, US net ~$300k, $2.8B global peak; other indications at stated PoS; respiratory bottom-up.)
A2: Scenario index (1=Failure..5=Blue-sky) | C2: 3
A4: Scenario levers (green = pulled from Drivers)
A5: COVID revenue multiplier | C5: =INDEX(Drivers!$D$39:$H$39,$C$2) -> 1
A6: Flu (mFLUSIVA) peak multiplier | C6: =INDEX(Drivers!$D$40:$H$40,$C$2) -> 1
A7: Flu+COVID combo peak multiplier | C7: =INDEX(Drivers!$D$41:$H$41,$C$2) -> 1
A8: Norovirus PoS | C8: =INDEX(Drivers!$D$42:$H$42,$C$2) -> 0.3
A9: Respiratory gross-margin shift | C9: =INDEX(Drivers!$D$43:$H$43,$C$2) -> 0
A10: INT melanoma PoS | C10: =INDEX(Drivers!$D$44:$H$44,$C$2) -> 0.88
A11: INT melanoma peak global sales ($B, before price factor) | C11: =INDEX(Drivers!$D$45:$H$45,$C$2) -> 2.8
A12: INT melanoma launch year | C12: =INDEX(Drivers!$D$46:$H$46,$C$2) -> 2027
A13: INT other-indication PoS multiplier (>=10 => all 100%) | C13: =INDEX(Drivers!$D$47:$H$47,$C$2) -> 1
A14: INT other-indication peak multiplier | C14: =INDEX(Drivers!$D$48:$H$48,$C$2) -> 1
A15: INT price factor (1.0 = US net ~$300k) | C15: =INDEX(Drivers!$D$49:$H$49,$C$2) -> 1
A16: INT mature profit-pool margin | C16: =INDEX(Drivers!$D$50:$H$50,$C$2) -> 0.55
A17: Unallocated R&D multiplier | C17: =INDEX(Drivers!$D$51:$H$51,$C$2) -> 1
A18: Future-pipeline credit factor | C18: =INDEX(Drivers!$D$52:$H$52,$C$2) -> 0.75
A19: WACC | C19: =INDEX(Drivers!$D$53:$H$53,$C$2) -> 0.1043
A20: Terminal growth | C20: =INDEX(Drivers!$D$54:$H$54,$C$2) -> 0
A21: Other patent litigation (expected cost) | C21: =INDEX(Drivers!$D$55:$H$55,$C$2) -> 0.5
A22: INT indications: scenario-adjusted launch / peak / PoS
A23: Indication | C23: Launch | D23: Peak | E23: PoS
A24: =Drivers!$B$95 -> Adjuvant melanoma IIB-IV (INTerpath-001) | C24: =$C$12 -> 2027 | D24: =$C$11 -> 2.8 | E24: =$C$10 -> 0.88
A25: =Drivers!$B$96 -> Adjuvant NSCLC II-IIIB (INTerpath-002) | C25: =Drivers!$D$96 -> 2031 | D25: =Drivers!$E$96*$C$14 -> 4 | E25: =MIN(Drivers!$F$96*$C$13,IF($C$13>=10,1,0.95)) -> 0.45
A26: =Drivers!$B$97 -> Post-neoadjuvant non-pCR NSCLC (INTerpath-009) | C26: =Drivers!$D$97 -> 2034 | D26: =Drivers!$E$97*$C$14 -> 1.5 | E26: =MIN(Drivers!$F$97*$C$13,IF($C$13>=10,1,0.95)) -> 0.4
A27: =Drivers!$B$98 -> Resected stage I NSCLC (INTerpath-014) | C27: =Drivers!$D$98 -> 2035 | D27: =Drivers!$E$98*$C$14 -> 2.5 | E27: =MIN(Drivers!$F$98*$C$13,IF($C$13>=10,1,0.95)) -> 0.35
A28: =Drivers!$B$99 -> Adjuvant RCC (INTerpath-004) | C28: =Drivers!$D$99 -> 2031 | D28: =Drivers!$E$99*$C$14 -> 1.2 | E28: =MIN(Drivers!$F$99*$C$13,IF($C$13>=10,1,0.95)) -> 0.25
A29: =Drivers!$B$100 -> MIBC adjuvant (INTerpath-005) | C29: =Drivers!$D$100 -> 2033 | D29: =Drivers!$E$100*$C$14 -> 1 | E29: =MIN(Drivers!$F$100*$C$13,IF($C$13>=10,1,0.95)) -> 0.2
A30: =Drivers!$B$101 -> NMIBC + BCG (INTerpath-011) | C30: =Drivers!$D$101 -> 2034 | D30: =Drivers!$E$101*$C$14 -> 1 | E30: =MIN(Drivers!$F$101*$C$13,IF($C$13>=10,1,0.95)) -> 0.15
A31: =Drivers!$B$102 -> 1L advanced melanoma (INTerpath-012) | C31: =Drivers!$D$102 -> 2031 | D31: =Drivers!$E$102*$C$14 -> 0.8 | E31: =MIN(Drivers!$F$102*$C$13,IF($C$13>=10,1,0.95)) -> 0.2
A32: =Drivers!$B$103 -> 1L metastatic squamous NSCLC (INTerpath-013) | C32: =Drivers!$D$103 -> 2032 | D32: =Drivers!$E$103*$C$14 -> 1.2 | E32: =MIN(Drivers!$F$103*$C$13,IF($C$13>=10,1,0.95)) -> 0.15
A33: =Drivers!$B$104 -> Other solid tumours - future INT indications (pre-Ph2) | C33: =Drivers!$D$104 -> 2035 | D33: =Drivers!$E$104*$C$14 -> 6 | E33: =MIN(Drivers!$F$104*$C$13,IF($C$13>=10,1,0.95)) -> 0.1
A35: Year | B35: unit | C35: 2027 | D35: 2028 | E35: 2029 | F35: 2030 | G35: 2031 | H35: 2032 | I35: 2033 | J35: 2034 | K35: 2035 | L35: 2036 | M35: 2037 | N35: 2038 | O35: 2039 | P35: 2040 | Q35: 2041 | R35: 2042 | S35: 2043 | T35: 2044 | U35: 2045
A36: Year index i | C36: 0 | D36: 1 | E36: 2 | F36: 3 | G36: 4 | H36: 5 | I36: 6 | J36: 7 | K36: 8 | L36: 9 | M36: 10 | N36: 11 | O36: 12 | P36: 13 | Q36: 14 | R36: 15 | S36: 16 | T36: 17 | U36: 18
A37: RESPIRATORY FRANCHISE
A38: COVID (Spikevax, mNEXSPIKE, partnerships) | B38: $B | C38: =Drivers!$D$60*$C$5 -> 1.85 | D38: =Drivers!$E$60*$C$5 -> 1.7 | E38: =Drivers!$F$60*$C$5 -> 1.55 | F38: =Drivers!$G$60*$C$5 -> 1.45 | G38: =Drivers!$H$60*$C$5 -> 1.38 | H38: =Drivers!$I$60*$C$5 -> 1.3 | I38: =H38*(1+Drivers!$C$61) -> 1.274 | J38: =I38*(1+Drivers!$C$61) -> 1.24852 | K38: =J38*(1+Drivers!$C$61) -> 1.2235496 | L38: =K38*(1+Drivers!$C$61) -> 1.1990786 | M38: =L38*(1+Drivers!$C$61) -> 1.175097 | N38: =M38*(1+Drivers!$C$61) -> 1.1515951 | O38: =N38*(1+Drivers!$C$61) -> 1.1285632 | P38: =O38*(1+Drivers!$C$61) -> 1.1059919 | ... U38: =T38*(1+Drivers!$C$61) -> 0.99972911
A39: Flu (mFLUSIVA) | B39: $B | C39: =Drivers!$C$62*IF((C$35-Drivers!$C$63)<0,0,MIN(((C$35-Drivers!$C$63)+1)/Drivers!$C$64,1))*$C$6 -> 0.16 | D39: =Drivers!$C$62*IF((D$35-Drivers!$C$63)<0,0,MIN(((D$35-Drivers!$C$63)+1)/Drivers!$C$64,1))*$C$6 -> 0.32 | E39: =Drivers!$C$62*IF((E$35-Drivers!$C$63)<0,0,MIN(((E$35-Drivers!$C$63)+1)/Drivers!$C$64,1))*$C$6 -> 0.48 | F39: =Drivers!$C$62*IF((F$35-Drivers!$C$63)<0,0,MIN(((F$35-Drivers!$C$63)+1)/Drivers!$C$64,1))*$C$6 -> 0.64 | G39: =Drivers!$C$62*IF((G$35-Drivers!$C$63)<0,0,MIN(((G$35-Drivers!$C$63)+1)/Drivers!$C$64,1))*$C$6 -> 0.8 | H39: =Drivers!$C$62*IF((H$35-Drivers!$C$63)<0,0,MIN(((H$35-Drivers!$C$63)+1)/Drivers!$C$64,1))*$C$6 -> 0.8 | I39: =Drivers!$C$62*IF((I$35-Drivers!$C$63)<0,0,MIN(((I$35-Drivers!$C$63)+1)/Drivers!$C$64,1))*$C$6 -> 0.8 | J39: =Drivers!$C$62*IF((J$35-Drivers!$C$63)<0,0,MIN(((J$35-Drivers!$C$63)+1)/Drivers!$C$64,1))*$C$6 -> 0.8 | ... U39: =Drivers!$C$62*IF((U$35-Drivers!$C$63)<0,0,MIN(((U$35-Drivers!$C$63)+1)/Drivers!$C$64,1))*$C$6 -> 0.8
A40: Flu+COVID combo (mCOMBRIAX) | B40: $B | C40: =Drivers!$C$65*IF((C$35-Drivers!$C$66)<0,0,MIN(((C$35-Drivers!$C$66)+1)/Drivers!$C$67,1))*$C$7*((1-Drivers!$C$69)+Drivers!$C$69*Drivers!$C$68) -> 0.2338 | D40: =Drivers!$C$65*IF((D$35-Drivers!$C$66)<0,0,MIN(((D$35-Drivers!$C$66)+1)/Drivers!$C$67,1))*$C$7*((1-Drivers!$C$69)+Drivers!$C$69*Drivers!$C$68) -> 0.4676 | E40: =Drivers!$C$65*IF((E$35-Drivers!$C$66)<0,0,MIN(((E$35-Drivers!$C$66)+1)/Drivers!$C$67,1))*$C$7*((1-Drivers!$C$69)+Drivers!$C$69*Drivers!$C$68) -> 0.7014 | F40: =Drivers!$C$65*IF((F$35-Drivers!$C$66)<0,0,MIN(((F$35-Drivers!$C$66)+1)/Drivers!$C$67,1))*$C$7*((1-Drivers!$C$69)+Drivers!$C$69*Drivers!$C$68) -> 0.9352 | G40: =Drivers!$C$65*IF((G$35-Drivers!$C$66)<0,0,MIN(((G$35-Drivers!$C$66)+1)/Drivers!$C$67,1))*$C$7*((1-Drivers!$C$69)+Drivers!$C$69*Drivers!$C$68) -> 1.169 | H40: =Drivers!$C$65*IF((H$35-Drivers!$C$66)<0,0,MIN(((H$35-Drivers!$C$66)+1)/Drivers!$C$67,1))*$C$7*((1-Drivers!$C$69)+Drivers!$C$69*Drivers!$C$68) -> 1.169 | I40: =Drivers!$C$65*IF((I$35-Drivers!$C$66)<0,0,MIN(((I$35-Drivers!$C$66)+1)/Drivers!$C$67,1))*$C$7*((1-Drivers!$C$69)+Drivers!$C$69*Drivers!$C$68) -> 1.169 | J40: =Drivers!$C$65*IF((J$35-Drivers!$C$66)<0,0,MIN(((J$35-Drivers!$C$66)+1)/Drivers!$C$67,1))*$C$7*((1-Drivers!$C$69)+Drivers!$C$69*Drivers!$C$68) -> 1.169 | ... U40: =Drivers!$C$65*IF((U$35-Drivers!$C$66)<0,0,MIN(((U$35-Drivers!$C$66)+1)/Drivers!$C$67,1))*$C$7*((1-Drivers!$C$69)+Drivers!$C$69*Drivers!$C$68) -> 1.169
A41: RSV (mRESVIA) | B41: $B | C41: =Drivers!$C$70*MIN((C$35-2026)/3,1) -> 0.05 | D41: =Drivers!$C$70*MIN((D$35-2026)/3,1) -> 0.1 | E41: =Drivers!$C$70*MIN((E$35-2026)/3,1) -> 0.15 | F41: =Drivers!$C$70*MIN((F$35-2026)/3,1) -> 0.15 | G41: =Drivers!$C$70*MIN((G$35-2026)/3,1) -> 0.15 | H41: =Drivers!$C$70*MIN((H$35-2026)/3,1) -> 0.15 | I41: =Drivers!$C$70*MIN((I$35-2026)/3,1) -> 0.15 | J41: =Drivers!$C$70*MIN((J$35-2026)/3,1) -> 0.15 | ... U41: =Drivers!$C$70*MIN((U$35-2026)/3,1) -> 0.15
A42: Norovirus (risk-adjusted) | B42: $B | C42: =$C$8*Drivers!$C$71*IF((C$35-Drivers!$C$72)<0,0,MIN(((C$35-Drivers!$C$72)+1)/Drivers!$C$73,1)) -> 0 | D42: =$C$8*Drivers!$C$71*IF((D$35-Drivers!$C$72)<0,0,MIN(((D$35-Drivers!$C$72)+1)/Drivers!$C$73,1)) -> 0 | E42: =$C$8*Drivers!$C$71*IF((E$35-Drivers!$C$72)<0,0,MIN(((E$35-Drivers!$C$72)+1)/Drivers!$C$73,1)) -> 0.072 | F42: =$C$8*Drivers!$C$71*IF((F$35-Drivers!$C$72)<0,0,MIN(((F$35-Drivers!$C$72)+1)/Drivers!$C$73,1)) -> 0.144 | G42: =$C$8*Drivers!$C$71*IF((G$35-Drivers!$C$72)<0,0,MIN(((G$35-Drivers!$C$72)+1)/Drivers!$C$73,1)) -> 0.216 | H42: =$C$8*Drivers!$C$71*IF((H$35-Drivers!$C$72)<0,0,MIN(((H$35-Drivers!$C$72)+1)/Drivers!$C$73,1)) -> 0.288 | I42: =$C$8*Drivers!$C$71*IF((I$35-Drivers!$C$72)<0,0,MIN(((I$35-Drivers!$C$72)+1)/Drivers!$C$73,1)) -> 0.36 | J42: =$C$8*Drivers!$C$71*IF((J$35-Drivers!$C$72)<0,0,MIN(((J$35-Drivers!$C$72)+1)/Drivers!$C$73,1)) -> 0.36 | ... U42: =$C$8*Drivers!$C$71*IF((U$35-Drivers!$C$72)<0,0,MIN(((U$35-Drivers!$C$72)+1)/Drivers!$C$73,1)) -> 0.36
...

Sheet M_Bull
A1: M_Bull - scenario model (Strong ESMO HR (~0.55) with OS trend; US net ~$420k (William Blair models $475k WAC); melanoma peak $5B; other INT PoS x1.33 incl. future tumours; respiratory ~$5-6B (mgmt path).)
A2: Scenario index (1=Failure..5=Blue-sky) | C2: 4
A4: Scenario levers (green = pulled from Drivers)
A5: COVID revenue multiplier | C5: =INDEX(Drivers!$D$39:$H$39,$C$2) -> 1.1
A6: Flu (mFLUSIVA) peak multiplier | C6: =INDEX(Drivers!$D$40:$H$40,$C$2) -> 1.6
A7: Flu+COVID combo peak multiplier | C7: =INDEX(Drivers!$D$41:$H$41,$C$2) -> 1.6
A8: Norovirus PoS | C8: =INDEX(Drivers!$D$42:$H$42,$C$2) -> 0.45
A9: Respiratory gross-margin shift | C9: =INDEX(Drivers!$D$43:$H$43,$C$2) -> 0.02
A10: INT melanoma PoS | C10: =INDEX(Drivers!$D$44:$H$44,$C$2) -> 0.93
A11: INT melanoma peak global sales ($B, before price factor) | C11: =INDEX(Drivers!$D$45:$H$45,$C$2) -> 5
A12: INT melanoma launch year | C12: =INDEX(Drivers!$D$46:$H$46,$C$2) -> 2027
A13: INT other-indication PoS multiplier (>=10 => all 100%) | C13: =INDEX(Drivers!$D$47:$H$47,$C$2) -> 1.33
A14: INT other-indication peak multiplier | C14: =INDEX(Drivers!$D$48:$H$48,$C$2) -> 1.2
A15: INT price factor (1.0 = US net ~$300k) | C15: =INDEX(Drivers!$D$49:$H$49,$C$2) -> 1.4
A16: INT mature profit-pool margin | C16: =INDEX(Drivers!$D$50:$H$50,$C$2) -> 0.55
A17: Unallocated R&D multiplier | C17: =INDEX(Drivers!$D$51:$H$51,$C$2) -> 1.05
A18: Future-pipeline credit factor | C18: =INDEX(Drivers!$D$52:$H$52,$C$2) -> 1
A19: WACC | C19: =INDEX(Drivers!$D$53:$H$53,$C$2) -> 0.1043
A20: Terminal growth | C20: =INDEX(Drivers!$D$54:$H$54,$C$2) -> 0.01
A21: Other patent litigation (expected cost) | C21: =INDEX(Drivers!$D$55:$H$55,$C$2) -> 0.3
A22: INT indications: scenario-adjusted launch / peak / PoS
A23: Indication | C23: Launch | D23: Peak | E23: PoS
A24: =Drivers!$B$95 -> Adjuvant melanoma IIB-IV (INTerpath-001) | C24: =$C$12 -> 2027 | D24: =$C$11 -> 5 | E24: =$C$10 -> 0.93
A25: =Drivers!$B$96 -> Adjuvant NSCLC II-IIIB (INTerpath-002) | C25: =Drivers!$D$96 -> 2031 | D25: =Drivers!$E$96*$C$14 -> 4.8 | E25: =MIN(Drivers!$F$96*$C$13,IF($C$13>=10,1,0.95)) -> 0.5985
A26: =Drivers!$B$97 -> Post-neoadjuvant non-pCR NSCLC (INTerpath-009) | C26: =Drivers!$D$97 -> 2034 | D26: =Drivers!$E$97*$C$14 -> 1.8 | E26: =MIN(Drivers!$F$97*$C$13,IF($C$13>=10,1,0.95)) -> 0.532
A27: =Drivers!$B$98 -> Resected stage I NSCLC (INTerpath-014) | C27: =Drivers!$D$98 -> 2035 | D27: =Drivers!$E$98*$C$14 -> 3 | E27: =MIN(Drivers!$F$98*$C$13,IF($C$13>=10,1,0.95)) -> 0.4655
A28: =Drivers!$B$99 -> Adjuvant RCC (INTerpath-004) | C28: =Drivers!$D$99 -> 2031 | D28: =Drivers!$E$99*$C$14 -> 1.44 | E28: =MIN(Drivers!$F$99*$C$13,IF($C$13>=10,1,0.95)) -> 0.3325
A29: =Drivers!$B$100 -> MIBC adjuvant (INTerpath-005) | C29: =Drivers!$D$100 -> 2033 | D29: =Drivers!$E$100*$C$14 -> 1.2 | E29: =MIN(Drivers!$F$100*$C$13,IF($C$13>=10,1,0.95)) -> 0.266
A30: =Drivers!$B$101 -> NMIBC + BCG (INTerpath-011) | C30: =Drivers!$D$101 -> 2034 | D30: =Drivers!$E$101*$C$14 -> 1.2 | E30: =MIN(Drivers!$F$101*$C$13,IF($C$13>=10,1,0.95)) -> 0.1995
A31: =Drivers!$B$102 -> 1L advanced melanoma (INTerpath-012) | C31: =Drivers!$D$102 -> 2031 | D31: =Drivers!$E$102*$C$14 -> 0.96 | E31: =MIN(Drivers!$F$102*$C$13,IF($C$13>=10,1,0.95)) -> 0.266
A32: =Drivers!$B$103 -> 1L metastatic squamous NSCLC (INTerpath-013) | C32: =Drivers!$D$103 -> 2032 | D32: =Drivers!$E$103*$C$14 -> 1.44 | E32: =MIN(Drivers!$F$103*$C$13,IF($C$13>=10,1,0.95)) -> 0.1995
A33: =Drivers!$B$104 -> Other solid tumours - future INT indications (pre-Ph2) | C33: =Drivers!$D$104 -> 2035 | D33: =Drivers!$E$104*$C$14 -> 7.2 | E33: =MIN(Drivers!$F$104*$C$13,IF($C$13>=10,1,0.95)) -> 0.133
A35: Year | B35: unit | C35: 2027 | D35: 2028 | E35: 2029 | F35: 2030 | G35: 2031 | H35: 2032 | I35: 2033 | J35: 2034 | K35: 2035 | L35: 2036 | M35: 2037 | N35: 2038 | O35: 2039 | P35: 2040 | Q35: 2041 | R35: 2042 | S35: 2043 | T35: 2044 | U35: 2045
A36: Year index i | C36: 0 | D36: 1 | E36: 2 | F36: 3 | G36: 4 | H36: 5 | I36: 6 | J36: 7 | K36: 8 | L36: 9 | M36: 10 | N36: 11 | O36: 12 | P36: 13 | Q36: 14 | R36: 15 | S36: 16 | T36: 17 | U36: 18
A37: RESPIRATORY FRANCHISE
A38: COVID (Spikevax, mNEXSPIKE, partnerships) | B38: $B | C38: =Drivers!$D$60*$C$5 -> 2.035 | D38: =Drivers!$E$60*$C$5 -> 1.87 | E38: =Drivers!$F$60*$C$5 -> 1.705 | F38: =Drivers!$G$60*$C$5 -> 1.595 | G38: =Drivers!$H$60*$C$5 -> 1.518 | H38: =Drivers!$I$60*$C$5 -> 1.43 | I38: =H38*(1+Drivers!$C$61) -> 1.4014 | J38: =I38*(1+Drivers!$C$61) -> 1.373372 | K38: =J38*(1+Drivers!$C$61) -> 1.3459046 | L38: =K38*(1+Drivers!$C$61) -> 1.3189865 | M38: =L38*(1+Drivers!$C$61) -> 1.2926067 | N38: =M38*(1+Drivers!$C$61) -> 1.2667546 | O38: =N38*(1+Drivers!$C$61) -> 1.2414195 | P38: =O38*(1+Drivers!$C$61) -> 1.2165911 | ... U38: =T38*(1+Drivers!$C$61) -> 1.099702
A39: Flu (mFLUSIVA) | B39: $B | C39: =Drivers!$C$62*IF((C$35-Drivers!$C$63)<0,0,MIN(((C$35-Drivers!$C$63)+1)/Drivers!$C$64,1))*$C$6 -> 0.256 | D39: =Drivers!$C$62*IF((D$35-Drivers!$C$63)<0,0,MIN(((D$35-Drivers!$C$63)+1)/Drivers!$C$64,1))*$C$6 -> 0.512 | E39: =Drivers!$C$62*IF((E$35-Drivers!$C$63)<0,0,MIN(((E$35-Drivers!$C$63)+1)/Drivers!$C$64,1))*$C$6 -> 0.768 | F39: =Drivers!$C$62*IF((F$35-Drivers!$C$63)<0,0,MIN(((F$35-Drivers!$C$63)+1)/Drivers!$C$64,1))*$C$6 -> 1.024 | G39: =Drivers!$C$62*IF((G$35-Drivers!$C$63)<0,0,MIN(((G$35-Drivers!$C$63)+1)/Drivers!$C$64,1))*$C$6 -> 1.28 | H39: =Drivers!$C$62*IF((H$35-Drivers!$C$63)<0,0,MIN(((H$35-Drivers!$C$63)+1)/Drivers!$C$64,1))*$C$6 -> 1.28 | I39: =Drivers!$C$62*IF((I$35-Drivers!$C$63)<0,0,MIN(((I$35-Drivers!$C$63)+1)/Drivers!$C$64,1))*$C$6 -> 1.28 | J39: =Drivers!$C$62*IF((J$35-Drivers!$C$63)<0,0,MIN(((J$35-Drivers!$C$63)+1)/Drivers!$C$64,1))*$C$6 -> 1.28 | ... U39: =Drivers!$C$62*IF((U$35-Drivers!$C$63)<0,0,MIN(((U$35-Drivers!$C$63)+1)/Drivers!$C$64,1))*$C$6 -> 1.28
A40: Flu+COVID combo (mCOMBRIAX) | B40: $B | C40: =Drivers!$C$65*IF((C$35-Drivers!$C$66)<0,0,MIN(((C$35-Drivers!$C$66)+1)/Drivers!$C$67,1))*$C$7*((1-Drivers!$C$69)+Drivers!$C$69*Drivers!$C$68) -> 0.37408 | D40: =Drivers!$C$65*IF((D$35-Drivers!$C$66)<0,0,MIN(((D$35-Drivers!$C$66)+1)/Drivers!$C$67,1))*$C$7*((1-Drivers!$C$69)+Drivers!$C$69*Drivers!$C$68) -> 0.74816 | E40: =Drivers!$C$65*IF((E$35-Drivers!$C$66)<0,0,MIN(((E$35-Drivers!$C$66)+1)/Drivers!$C$67,1))*$C$7*((1-Drivers!$C$69)+Drivers!$C$69*Drivers!$C$68) -> 1.12224 | F40: =Drivers!$C$65*IF((F$35-Drivers!$C$66)<0,0,MIN(((F$35-Drivers!$C$66)+1)/Drivers!$C$67,1))*$C$7*((1-Drivers!$C$69)+Drivers!$C$69*Drivers!$C$68) -> 1.49632 | G40: =Drivers!$C$65*IF((G$35-Drivers!$C$66)<0,0,MIN(((G$35-Drivers!$C$66)+1)/Drivers!$C$67,1))*$C$7*((1-Drivers!$C$69)+Drivers!$C$69*Drivers!$C$68) -> 1.8704 | H40: =Drivers!$C$65*IF((H$35-Drivers!$C$66)<0,0,MIN(((H$35-Drivers!$C$66)+1)/Drivers!$C$67,1))*$C$7*((1-Drivers!$C$69)+Drivers!$C$69*Drivers!$C$68) -> 1.8704 | I40: =Drivers!$C$65*IF((I$35-Drivers!$C$66)<0,0,MIN(((I$35-Drivers!$C$66)+1)/Drivers!$C$67,1))*$C$7*((1-Drivers!$C$69)+Drivers!$C$69*Drivers!$C$68) -> 1.8704 | J40: =Drivers!$C$65*IF((J$35-Drivers!$C$66)<0,0,MIN(((J$35-Drivers!$C$66)+1)/Drivers!$C$67,1))*$C$7*((1-Drivers!$C$69)+Drivers!$C$69*Drivers!$C$68) -> 1.8704 | ... U40: =Drivers!$C$65*IF((U$35-Drivers!$C$66)<0,0,MIN(((U$35-Drivers!$C$66)+1)/Drivers!$C$67,1))*$C$7*((1-Drivers!$C$69)+Drivers!$C$69*Drivers!$C$68) -> 1.8704
A41: RSV (mRESVIA) | B41: $B | C41: =Drivers!$C$70*MIN((C$35-2026)/3,1) -> 0.05 | D41: =Drivers!$C$70*MIN((D$35-2026)/3,1) -> 0.1 | E41: =Drivers!$C$70*MIN((E$35-2026)/3,1) -> 0.15 | F41: =Drivers!$C$70*MIN((F$35-2026)/3,1) -> 0.15 | G41: =Drivers!$C$70*MIN((G$35-2026)/3,1) -> 0.15 | H41: =Drivers!$C$70*MIN((H$35-2026)/3,1) -> 0.15 | I41: =Drivers!$C$70*MIN((I$35-2026)/3,1) -> 0.15 | J41: =Drivers!$C$70*MIN((J$35-2026)/3,1) -> 0.15 | ... U41: =Drivers!$C$70*MIN((U$35-2026)/3,1) -> 0.15
A42: Norovirus (risk-adjusted) | B42: $B | C42: =$C$8*Drivers!$C$71*IF((C$35-Drivers!$C$72)<0,0,MIN(((C$35-Drivers!$C$72)+1)/Drivers!$C$73,1)) -> 0 | D42: =$C$8*Drivers!$C$71*IF((D$35-Drivers!$C$72)<0,0,MIN(((D$35-Drivers!$C$72)+1)/Drivers!$C$73,1)) -> 0 | E42: =$C$8*Drivers!$C$71*IF((E$35-Drivers!$C$72)<0,0,MIN(((E$35-Drivers!$C$72)+1)/Drivers!$C$73,1)) -> 0.108 | F42: =$C$8*Drivers!$C$71*IF((F$35-Drivers!$C$72)<0,0,MIN(((F$35-Drivers!$C$72)+1)/Drivers!$C$73,1)) -> 0.216 | G42: =$C$8*Drivers!$C$71*IF((G$35-Drivers!$C$72)<0,0,MIN(((G$35-Drivers!$C$72)+1)/Drivers!$C$73,1)) -> 0.324 | H42: =$C$8*Drivers!$C$71*IF((H$35-Drivers!$C$72)<0,0,MIN(((H$35-Drivers!$C$72)+1)/Drivers!$C$73,1)) -> 0.432 | I42: =$C$8*Drivers!$C$71*IF((I$35-Drivers!$C$72)<0,0,MIN(((I$35-Drivers!$C$72)+1)/Drivers!$C$73,1)) -> 0.54 | J42: =$C$8*Drivers!$C$71*IF((J$35-Drivers!$C$72)<0,0,MIN(((J$35-Drivers!$C$72)+1)/Drivers!$C$73,1)) -> 0.54 | ... U42: =$C$8*Drivers!$C$71*IF((U$35-Drivers!$C$72)<0,0,MIN(((U$35-Drivers!$C$72)+1)/Drivers!$C$73,1)) -> 0.54
...

Sheet M_BlueSky
A1: M_BlueSky - scenario model (Ceiling test, NOT weighted: every INT indication succeeds (PoS=100%), peaks x1.5, US net ~$475k (William Blair WAC), 62% margin, respiratory bull, WACC 8.0%, g=2%, R&D fully value-creating.)
A2: Scenario index (1=Failure..5=Blue-sky) | C2: 5
A4: Scenario levers (green = pulled from Drivers)
A5: COVID revenue multiplier | C5: =INDEX(Drivers!$D$39:$H$39,$C$2) -> 1.1
A6: Flu (mFLUSIVA) peak multiplier | C6: =INDEX(Drivers!$D$40:$H$40,$C$2) -> 1.6
A7: Flu+COVID combo peak multiplier | C7: =INDEX(Drivers!$D$41:$H$41,$C$2) -> 1.6
A8: Norovirus PoS | C8: =INDEX(Drivers!$D$42:$H$42,$C$2) -> 1
A9: Respiratory gross-margin shift | C9: =INDEX(Drivers!$D$43:$H$43,$C$2) -> 0.03
A10: INT melanoma PoS | C10: =INDEX(Drivers!$D$44:$H$44,$C$2) -> 1
A11: INT melanoma peak global sales ($B, before price factor) | C11: =INDEX(Drivers!$D$45:$H$45,$C$2) -> 6
A12: INT melanoma launch year | C12: =INDEX(Drivers!$D$46:$H$46,$C$2) -> 2027
A13: INT other-indication PoS multiplier (>=10 => all 100%) | C13: =INDEX(Drivers!$D$47:$H$47,$C$2) -> 10
A14: INT other-indication peak multiplier | C14: =INDEX(Drivers!$D$48:$H$48,$C$2) -> 1.5
A15: INT price factor (1.0 = US net ~$300k) | C15: =INDEX(Drivers!$D$49:$H$49,$C$2) -> 1.58
A16: INT mature profit-pool margin | C16: =INDEX(Drivers!$D$50:$H$50,$C$2) -> 0.62
A17: Unallocated R&D multiplier | C17: =INDEX(Drivers!$D$51:$H$51,$C$2) -> 1
A18: Future-pipeline credit factor | C18: =INDEX(Drivers!$D$52:$H$52,$C$2) -> 1
A19: WACC | C19: =INDEX(Drivers!$D$53:$H$53,$C$2) -> 0.08
A20: Terminal growth | C20: =INDEX(Drivers!$D$54:$H$54,$C$2) -> 0.02
A21: Other patent litigation (expected cost) | C21: =INDEX(Drivers!$D$55:$H$55,$C$2) -> 0.3
A22: INT indications: scenario-adjusted launch / peak / PoS
A23: Indication | C23: Launch | D23: Peak | E23: PoS
A24: =Drivers!$B$95 -> Adjuvant melanoma IIB-IV (INTerpath-001) | C24: =$C$12 -> 2027 | D24: =$C$11 -> 6 | E24: =$C$10 -> 1
A25: =Drivers!$B$96 -> Adjuvant NSCLC II-IIIB (INTerpath-002) | C25: =Drivers!$D$96 -> 2031 | D25: =Drivers!$E$96*$C$14 -> 6 | E25: =MIN(Drivers!$F$96*$C$13,IF($C$13>=10,1,0.95)) -> 1
A26: =Drivers!$B$97 -> Post-neoadjuvant non-pCR NSCLC (INTerpath-009) | C26: =Drivers!$D$97 -> 2034 | D26: =Drivers!$E$97*$C$14 -> 2.25 | E26: =MIN(Drivers!$F$97*$C$13,IF($C$13>=10,1,0.95)) -> 1
A27: =Drivers!$B$98 -> Resected stage I NSCLC (INTerpath-014) | C27: =Drivers!$D$98 -> 2035 | D27: =Drivers!$E$98*$C$14 -> 3.75 | E27: =MIN(Drivers!$F$98*$C$13,IF($C$13>=10,1,0.95)) -> 1
A28: =Drivers!$B$99 -> Adjuvant RCC (INTerpath-004) | C28: =Drivers!$D$99 -> 2031 | D28: =Drivers!$E$99*$C$14 -> 1.8 | E28: =MIN(Drivers!$F$99*$C$13,IF($C$13>=10,1,0.95)) -> 1
A29: =Drivers!$B$100 -> MIBC adjuvant (INTerpath-005) | C29: =Drivers!$D$100 -> 2033 | D29: =Drivers!$E$100*$C$14 -> 1.5 | E29: =MIN(Drivers!$F$100*$C$13,IF($C$13>=10,1,0.95)) -> 1
A30: =Drivers!$B$101 -> NMIBC + BCG (INTerpath-011) | C30: =Drivers!$D$101 -> 2034 | D30: =Drivers!$E$101*$C$14 -> 1.5 | E30: =MIN(Drivers!$F$101*$C$13,IF($C$13>=10,1,0.95)) -> 1
A31: =Drivers!$B$102 -> 1L advanced melanoma (INTerpath-012) | C31: =Drivers!$D$102 -> 2031 | D31: =Drivers!$E$102*$C$14 -> 1.2 | E31: =MIN(Drivers!$F$102*$C$13,IF($C$13>=10,1,0.95)) -> 1
A32: =Drivers!$B$103 -> 1L metastatic squamous NSCLC (INTerpath-013) | C32: =Drivers!$D$103 -> 2032 | D32: =Drivers!$E$103*$C$14 -> 1.8 | E32: =MIN(Drivers!$F$103*$C$13,IF($C$13>=10,1,0.95)) -> 1
A33: =Drivers!$B$104 -> Other solid tumours - future INT indications (pre-Ph2) | C33: =Drivers!$D$104 -> 2035 | D33: =Drivers!$E$104*$C$14 -> 9 | E33: =MIN(Drivers!$F$104*$C$13,IF($C$13>=10,1,0.95)) -> 1
A35: Year | B35: unit | C35: 2027 | D35: 2028 | E35: 2029 | F35: 2030 | G35: 2031 | H35: 2032 | I35: 2033 | J35: 2034 | K35: 2035 | L35: 2036 | M35: 2037 | N35: 2038 | O35: 2039 | P35: 2040 | Q35: 2041 | R35: 2042 | S35: 2043 | T35: 2044 | U35: 2045
A36: Year index i | C36: 0 | D36: 1 | E36: 2 | F36: 3 | G36: 4 | H36: 5 | I36: 6 | J36: 7 | K36: 8 | L36: 9 | M36: 10 | N36: 11 | O36: 12 | P36: 13 | Q36: 14 | R36: 15 | S36: 16 | T36: 17 | U36: 18
A37: RESPIRATORY FRANCHISE
A38: COVID (Spikevax, mNEXSPIKE, partnerships) | B38: $B | C38: =Drivers!$D$60*$C$5 -> 2.035 | D38: =Drivers!$E$60*$C$5 -> 1.87 | E38: =Drivers!$F$60*$C$5 -> 1.705 | F38: =Drivers!$G$60*$C$5 -> 1.595 | G38: =Drivers!$H$60*$C$5 -> 1.518 | H38: =Drivers!$I$60*$C$5 -> 1.43 | I38: =H38*(1+Drivers!$C$61) -> 1.4014 | J38: =I38*(1+Drivers!$C$61) -> 1.373372 | K38: =J38*(1+Drivers!$C$61) -> 1.3459046 | L38: =K38*(1+Drivers!$C$61) -> 1.3189865 | M38: =L38*(1+Drivers!$C$61) -> 1.2926067 | N38: =M38*(1+Drivers!$C$61) -> 1.2667546 | O38: =N38*(1+Drivers!$C$61) -> 1.2414195 | P38: =O38*(1+Drivers!$C$61) -> 1.2165911 | ... U38: =T38*(1+Drivers!$C$61) -> 1.099702
A39: Flu (mFLUSIVA) | B39: $B | C39: =Drivers!$C$62*IF((C$35-Drivers!$C$63)<0,0,MIN(((C$35-Drivers!$C$63)+1)/Drivers!$C$64,1))*$C$6 -> 0.256 | D39: =Drivers!$C$62*IF((D$35-Drivers!$C$63)<0,0,MIN(((D$35-Drivers!$C$63)+1)/Drivers!$C$64,1))*$C$6 -> 0.512 | E39: =Drivers!$C$62*IF((E$35-Drivers!$C$63)<0,0,MIN(((E$35-Drivers!$C$63)+1)/Drivers!$C$64,1))*$C$6 -> 0.768 | F39: =Drivers!$C$62*IF((F$35-Drivers!$C$63)<0,0,MIN(((F$35-Drivers!$C$63)+1)/Drivers!$C$64,1))*$C$6 -> 1.024 | G39: =Drivers!$C$62*IF((G$35-Drivers!$C$63)<0,0,MIN(((G$35-Drivers!$C$63)+1)/Drivers!$C$64,1))*$C$6 -> 1.28 | H39: =Drivers!$C$62*IF((H$35-Drivers!$C$63)<0,0,MIN(((H$35-Drivers!$C$63)+1)/Drivers!$C$64,1))*$C$6 -> 1.28 | I39: =Drivers!$C$62*IF((I$35-Drivers!$C$63)<0,0,MIN(((I$35-Drivers!$C$63)+1)/Drivers!$C$64,1))*$C$6 -> 1.28 | J39: =Drivers!$C$62*IF((J$35-Drivers!$C$63)<0,0,MIN(((J$35-Drivers!$C$63)+1)/Drivers!$C$64,1))*$C$6 -> 1.28 | ... U39: =Drivers!$C$62*IF((U$35-Drivers!$C$63)<0,0,MIN(((U$35-Drivers!$C$63)+1)/Drivers!$C$64,1))*$C$6 -> 1.28
A40: Flu+COVID combo (mCOMBRIAX) | B40: $B | C40: =Drivers!$C$65*IF((C$35-Drivers!$C$66)<0,0,MIN(((C$35-Drivers!$C$66)+1)/Drivers!$C$67,1))*$C$7*((1-Drivers!$C$69)+Drivers!$C$69*Drivers!$C$68) -> 0.37408 | D40: =Drivers!$C$65*IF((D$35-Drivers!$C$66)<0,0,MIN(((D$35-Drivers!$C$66)+1)/Drivers!$C$67,1))*$C$7*((1-Drivers!$C$69)+Drivers!$C$69*Drivers!$C$68) -> 0.74816 | E40: =Drivers!$C$65*IF((E$35-Drivers!$C$66)<0,0,MIN(((E$35-Drivers!$C$66)+1)/Drivers!$C$67,1))*$C$7*((1-Drivers!$C$69)+Drivers!$C$69*Drivers!$C$68) -> 1.12224 | F40: =Drivers!$C$65*IF((F$35-Drivers!$C$66)<0,0,MIN(((F$35-Drivers!$C$66)+1)/Drivers!$C$67,1))*$C$7*((1-Drivers!$C$69)+Drivers!$C$69*Drivers!$C$68) -> 1.49632 | G40: =Drivers!$C$65*IF((G$35-Drivers!$C$66)<0,0,MIN(((G$35-Drivers!$C$66)+1)/Drivers!$C$67,1))*$C$7*((1-Drivers!$C$69)+Drivers!$C$69*Drivers!$C$68) -> 1.8704 | H40: =Drivers!$C$65*IF((H$35-Drivers!$C$66)<0,0,MIN(((H$35-Drivers!$C$66)+1)/Drivers!$C$67,1))*$C$7*((1-Drivers!$C$69)+Drivers!$C$69*Drivers!$C$68) -> 1.8704 | I40: =Drivers!$C$65*IF((I$35-Drivers!$C$66)<0,0,MIN(((I$35-Drivers!$C$66)+1)/Drivers!$C$67,1))*$C$7*((1-Drivers!$C$69)+Drivers!$C$69*Drivers!$C$68) -> 1.8704 | J40: =Drivers!$C$65*IF((J$35-Drivers!$C$66)<0,0,MIN(((J$35-Drivers!$C$66)+1)/Drivers!$C$67,1))*$C$7*((1-Drivers!$C$69)+Drivers!$C$69*Drivers!$C$68) -> 1.8704 | ... U40: =Drivers!$C$65*IF((U$35-Drivers!$C$66)<0,0,MIN(((U$35-Drivers!$C$66)+1)/Drivers!$C$67,1))*$C$7*((1-Drivers!$C$69)+Drivers!$C$69*Drivers!$C$68) -> 1.8704
A41: RSV (mRESVIA) | B41: $B | C41: =Drivers!$C$70*MIN((C$35-2026)/3,1) -> 0.05 | D41: =Drivers!$C$70*MIN((D$35-2026)/3,1) -> 0.1 | E41: =Drivers!$C$70*MIN((E$35-2026)/3,1) -> 0.15 | F41: =Drivers!$C$70*MIN((F$35-2026)/3,1) -> 0.15 | G41: =Drivers!$C$70*MIN((G$35-2026)/3,1) -> 0.15 | H41: =Drivers!$C$70*MIN((H$35-2026)/3,1) -> 0.15 | I41: =Drivers!$C$70*MIN((I$35-2026)/3,1) -> 0.15 | J41: =Drivers!$C$70*MIN((J$35-2026)/3,1) -> 0.15 | ... U41: =Drivers!$C$70*MIN((U$35-2026)/3,1) -> 0.15
A42: Norovirus (risk-adjusted) | B42: $B | C42: =$C$8*Drivers!$C$71*IF((C$35-Drivers!$C$72)<0,0,MIN(((C$35-Drivers!$C$72)+1)/Drivers!$C$73,1)) -> 0 | D42: =$C$8*Drivers!$C$71*IF((D$35-Drivers!$C$72)<0,0,MIN(((D$35-Drivers!$C$72)+1)/Drivers!$C$73,1)) -> 0 | E42: =$C$8*Drivers!$C$71*IF((E$35-Drivers!$C$72)<0,0,MIN(((E$35-Drivers!$C$72)+1)/Drivers!$C$73,1)) -> 0.24 | F42: =$C$8*Drivers!$C$71*IF((F$35-Drivers!$C$72)<0,0,MIN(((F$35-Drivers!$C$72)+1)/Drivers!$C$73,1)) -> 0.48 | G42: =$C$8*Drivers!$C$71*IF((G$35-Drivers!$C$72)<0,0,MIN(((G$35-Drivers!$C$72)+1)/Drivers!$C$73,1)) -> 0.72 | H42: =$C$8*Drivers!$C$71*IF((H$35-Drivers!$C$72)<0,0,MIN(((H$35-Drivers!$C$72)+1)/Drivers!$C$73,1)) -> 0.96 | I42: =$C$8*Drivers!$C$71*IF((I$35-Drivers!$C$72)<0,0,MIN(((I$35-Drivers!$C$72)+1)/Drivers!$C$73,1)) -> 1.2 | J42: =$C$8*Drivers!$C$71*IF((J$35-Drivers!$C$72)<0,0,MIN(((J$35-Drivers!$C$72)+1)/Drivers!$C$73,1)) -> 1.2 | ... U42: =$C$8*Drivers!$C$71*IF((U$35-Drivers!$C$72)<0,0,MIN(((U$35-Drivers!$C$72)+1)/Drivers!$C$73,1)) -> 1.2
...

Sheet History
A1: Normalized 5-year history ($ millions; margins as %)
A2: Source: SEC XBRL companyfacts (data/xbrl_annual.csv, xbrl_quarterly.csv) via scripts/xbrl_financials.py + diagnostics.py. EBIT_norm adds back the $882m Arbutus settlement charge (TTM). Write-downs recurred 2022-25 and are NOT added back.
A4: line item | B4: 2021 | C4: 2022 | D4: 2023 | E4: 2024 | F4: 2025 | G4: TTM Q2-26
A5: Revenue | B5: 18471 | C5: 19263 | D5: 6848 | E5: 3236 | F5: 1944 | G5: 2228
A6: COGS | B6: 2617 | C6: 5416 | D6: 4693 | E6: 1464 | F6: 868 | G6: 1707
A7: RnD | B7: 1991 | C7: 3295 | D7: 4845 | E7: 4543 | F7: 3132 | G7: 2876
A8: SGA | B8: 567 | C8: 1132 | D8: 1549 | E8: 1174 | F8: 1018 | G8: 965
A9: EBIT | B9: 13296 | C9: 9420 | D9: -4239 | E9: -3945 | F9: -3074 | G9: -3320
A10: SBC | B10: 142 | C10: 226 | D10: 305 | E10: 429 | F10: 483 | G10: 462
A11: DandA | B11: 232 | C11: 348 | D11: 617 | E11: 185 | F11: 211 | G11: 229
A12: WriteDowns | B12: 0 | C12: 1917 | D12: 2341 | E12: 555 | F12: 315 | G12: 297
A13: InterestIncome | B13: 18 | C13: 200 | D13: 421 | E13: 425 | F13: 314 | G13: 282
A14: NetIncome | B14: 12202 | C14: 8362 | D14: -4714 | E14: -3561 | F14: -2822 | G14: -3151
A15: CFO | B15: 13620 | C15: 4981 | D15: -3118 | E15: -3004 | F15: -1873 | G15: -1073
A16: Capex | B16: 284 | C16: 400 | D16: 707 | E16: 1051 | F16: 192 | G16: 171
A17: TaxesPaid | B17: 480 | C17: 2729 | D17: -357 | E17: 197 | F17: 26
A18: Cash | B18: 6848 | C18: 3205 | D18: 2907 | E18: 1927 | F18: 2595 | G18: 1723
A19: Investments | B19: 10722 | C19: 15015 | D19: 10374 | E19: 7592 | F19: 5540 | G19: 5187
A20: TotalAssets | B20: 24669 | C20: 25858 | D20: 18426 | E20: 14142 | F20: 12338 | G20: 10961
A21: CurrentLiab | B21: 9128 | C21: 4923 | D21: 3015 | E21: 2206 | F21: 1987 | G21: 2534
A22: Equity | B22: 14145 | C22: 19123 | D22: 13854 | E22: 10901 | F22: 8650 | G22: 6761
A23: Receivables | B23: 3175 | C23: 1385 | D23: 892 | E23: 358 | F23: 184 | G23: 17
A24: Inventory | B24: 1441 | C24: 949 | D24: 202 | E24: 117 | F24: 153 | G24: 280
A25: DeferredRev | B25: 6868 | C25: 2711 | D25: 651 | E25: 211 | F25: 252 | G25: 442
A26: Debt | B26: 764 | C26: 1073 | D26: 575 | E26: 62 | F26: 635 | G26: 628
A27: DilutedShares | B27: 431 | C27: 416 | D27: 382 | E27: 384 | F27: 389 | G27: 398
A28: SharesOut | B28: 403 | C28: 385 | D28: 382 | E28: 386 | F28: 394 | G28: 399
A29: Buybacks | B29: 857 | C29: 3329 | D29: 1153 | E29: 0 | F29: 2 | G29: 0
... A42: NetCash | B42: 16806 | C42: 17147 | D42: 12706 | E42: 9457 | F42: 7500 | G42: 6282

Sheet CashBridge
A1: Net income -> CFO -> FCF bridge ($ millions)
A2: Source: data/cash_bridge.csv
A4: line | B4: 2021 | C4: 2022 | D4: 2023 | E4: 2024 | F4: 2025 | G4: TTM Q2-26
A5: NetIncome | B5: 12202 | C5: 8362 | D5: -4714 | E5: -3561 | F5: -2822 | G5: -3151
A6: SBC | B6: 142 | C6: 226 | D6: 305 | E6: 429 | F6: 483 | G6: 462
A7: DandA | B7: 232 | C7: 348 | D7: 617 | E7: 185 | F7: 211 | G7: 229
A8: WriteDowns(non-cash) | B8: 0 | C8: 1917 | D8: 2341 | E8: 555 | F8: 315 | G8: 297
